Workbook
Name ExternalData_1: 'UIUX 점검'!$A$1:$T$655

Sheet UIUX 점검
A1: 시나리오ID | B1: 테스트차수 | C1: 단계 | D1: 업무모듈명 | E1: 결함ID | F1: 결함내용 | G1: 테스트단계 | H1: PL | I1: 개발자 | J1: 테스터 | K1: 기능유형 | L1: 결함구분 | M1: 결함유형 | N1: 결함상태 | O1: 담당자 | P1: 심각도 | Q1: 조치상태 | R1: 결함등록일 | S1: 결함수정일시 | T1: 기각사유 | U1: 결함패턴_대분류 | V1: 결함패턴_중분류 | W1: 결함사유_요약 | X1: 결함사유_상세 | Y1: 기각사유_분석 | Z1: 기각사유_분류 | AA1: 조치권고
A2: UT-GO12705S | B2: 2-1차 | C2: 1 | D2: 공항운영(GO) | E2: DEF-00205 | F2: 기준일자 기준으로 검색해도 운항일자 날짜가 다름 ex) 2025-05-15 : 기준일자 => 운항일자=>20250605 | G2: 개발자테스트 | H2: 신문호 | I2: 김경준 | J2: 3자테스터공통 | K2: Online | L2: 결함 | M2: 데이터 | N2: 결함검토요청 | O2: 신문호 | P2: Major | Q2: 결함검토요청 | R2: 46139.619 | S2: 46139.619 | U2: 날짜/기간 처리 | V2: 기준일자/조회일자 불일치 | W2: 기준일자 기준으로 검색해도 운항일자 날짜가 다름 | X2: 기준일자 기준으로 검색해도 운항일자 날짜가 다름 ex) 2025-05-15 : 기준일자 => 운항일자=>20250605 | AA2: 날짜 컴포넌트 표준화, 기준일자-운항일자 등 필드 매핑 점검 및 기간 가드 추가
A3: UT-GO41701S | B3: 2-2차 | C3: 1 | D3: 공항운영(GO) | E3: DEF-00225 | F3: 운영년월의 년도입력간 validator 필요. 9999년도 이런식으로 입력이 가능합니다. | G3: 개발자테스트 | H3: 신문호 | I3: 신문호 | J3: 3자테스터공통 | K3: Online | L3: 개선/변경 | M3: 기능 | N3: 결함검토요청 | O3: 신문호 | P3: Minor | Q3: 결함검토요청 | R3: 46139.701 | S3: 46139.701 | U3: 날짜/기간 처리 | V3: 날짜 입력 유효성 | W3: 운영년월의 년도입력간 validator 필요. 9999년도 이런식으로 입력이 가능합니다. | X3: 운영년월의 년도입력간 validator 필요. 9999년도 이런식으로 입력이 가능합니다. | AA3: 날짜 컴포넌트 표준화, 기준일자-운항일자 등 필드 매핑 점검 및 기간 가드 추가
A4: UT-GO11950S | B4: 2-2차 | C4: 1 | D4: 공항운영(GO) | E4: DEF-00226 | F4: 주간 실적조회 엑셀 다운로드가 되지 않음(잘못올렸습니다 죄송합니다) | G4: 개발자테스트 | H4: 신문호 | I4: 신문호 | J4: 3자테스터공통 | K4: Online | L4: 결함 | M4: 기능 | N4: 결함검토요청 | O4: 신문호 | P4: Critical | Q4: 결함검토요청 | R4: 46139.705 | S4: 46139.715 | U4: 다운로드/출력 | V4: 엑셀 다운로드 오류 | W4: 주간 실적조회 엑셀 다운로드가 되지 않음(잘못올렸습니다 죄송합니다) | X4: 주간 실적조회 엑셀 다운로드가 되지 않음(잘못올렸습니다 죄송합니다) | AA4: 엑셀/PDF 공통 출력 모듈 점검, 컬럼 매핑·서식 검증 및 예외 처리
A5: UT-GO11950S | B5: 2-2차 | C5: 1 | D5: 공항운영(GO) | E5: DEF-00228 | F5: 일일 실적조회의 연간 그래프간 데이터가 존재하지 않을때 사용자가 이해가게끔 표시할수 있어야 할거 같습니다 | G5: 개발자테스트 | H5: 신문호 | I5: 신문호 | J5: 3자테스터공통 | K5: Online | L5: 개선/변경 | M5: UI | N5: 결함검토요청 | O5: 신문호 | P5: Minor | Q5: 결함검토요청 | R5: 46139.707 | S5: 46139.707 | U5: 시각화/그래프 표시 | V5: 무데이터 표시 미흡 | W5: 일일 실적조회의 연간 그래프간 데이터가 존재하지 않을때 사용자가 이해가게끔 표시할수 있어야 할거 같습니다 | X5: 일일 실적조회의 연간 그래프간 데이터가 존재하지 않을때 사용자가 이해가게끔 표시할수 있어야 할거 같습니다 | AA5: 차트 공통 컴포넌트 점검, 무데이터 처리 및 축/범례 표준화
A6: UT-GO11950S | B6: 2-2차 | C6: 1 | D6: 공항운영(GO) | E6: DEF-00229 | F6: 일일 실적조희의 그래프 버튼의 미동작 | G6: 개발자테스트 | H6: 신문호 | I6: 신문호 | J6: 3자테스터공통 | K6: Online | L6: 결함 | M6: 기능 | N6: 결함검토요청 | O6: 신문호 | P6: Minor | Q6: 결함검토요청 | R6: 46139.707 | S6: 46139.707 | U6: 시각화/그래프 표시 | V6: 차트 표시 오류 | W6: 일일 실적조희의 그래프 버튼의 미동작 | X6: 일일 실적조희의 그래프 버튼의 미동작 | AA6: 차트 공통 컴포넌트 점검, 무데이터 처리 및 축/범례 표준화
A7: UT-GO11960S | B7: 2-2차 | C7: 1 | D7: 공항운영(GO) | E7: DEF-00233 | F7: 일자부분에 다른 페이지와 다르게 required 빨간 표시가 안되어있음 | G7: 개발자테스트 | H7: 신문호 | I7: 신문호 | J7: 3자테스터공통 | K7: Online | L7: 개선/변경 | M7: UI | N7: 결함검토요청 | O7: 신문호 | P7: Minor | Q7: 결함검토요청 | R7: 46139.717 | S7: 46140.593 | U7: 날짜/기간 처리 | V7: 날짜 표시/포맷 | W7: 일자부분에 다른 페이지와 다르게 required 빨간 표시가 안되어있음 | X7: 일자부분에 다른 페이지와 다르게 required 빨간 표시가 안되어있음 | AA7: 날짜 컴포넌트 표준화, 기준일자-운항일자 등 필드 매핑 점검 및 기간 가드 추가
A8: UT-GO13303S | B8: 2-1차 | C8: 1 | D8: 공항운영(GO) | E8: DEF-00192 | F8: 빈 엑셀양식 다운로드 후 양식대로 데이터 삽입해도 업로드 실패하였습니다 발생 | G8: 개발자테스트 | H8: 신문호 | I8: 박정구 | J8: 3자테스터공통 | K8: Online | L8: 결함 | M8: 기능 | N8: 결함검토요청 | O8: 신문호 | P8: Major | Q8: 결함검토요청 | R8: 46139.598 | S8: 46139.598 | U8: 다운로드/출력 | V8: 엑셀 다운로드 오류 | W8: 빈 엑셀양식 다운로드 후 양식대로 데이터 삽입해도 업로드 실패하였습니다 발생 | X8: 빈 엑셀양식 다운로드 후 양식대로 데이터 삽입해도 업로드 실패하였습니다 발생 | AA8: 엑셀/PDF 공통 출력 모듈 점검, 컬럼 매핑·서식 검증 및 예외 처리
A9: UT-GO12909S | B9: 2-1차 | C9: 1 | D9: 공항운영(GO) | E9: DEF-00195 | F9: 12909S 테스트 시험내용과 화면이 일치하지않음 | G9: 개발자테스트 | H9: 신문호 | I9: 박정구 | J9: 3자테스터공통 | K9: Online | L9: 결함 | M9: 문서화 | N9: 결함검토요청 | O9: 신문호 | P9: Minor | Q9: 결함검토요청 | R9: 46139.599 | S9: 46139.599 | U9: 데이터 정합성/매핑 | V9: 데이터 정합성 | W9: 12909S 테스트 시험내용과 화면이 일치하지않음 | X9: 12909S 테스트 시험내용과 화면이 일치하지않음 | AA9: 원천 데이터-화면 매핑 재검증, 집계 로직 단위 테스트 보강
A10: UT-GO12511S | B10: 2-1차 | C10: 1 | D10: 공항운영(GO) | E10: DEF-00196 | F10: 화면 우측 상단의 Search 버튼과 주기 선택 이 겹침. 화면을 축소하면.. 화면이 더 일그러짐.. | G10: 개발자테스트 | H10: 신문호 | I10: 김경준 | J10: 3자테스터공통 | K10: Online | L10: 결함 | M10: UI | N10: 결함검토요청 | O10: 신문호 | P10: Minor | Q10: 결함검토요청 | R10: 46139.605 | S10: 46139.605 | U10: 시각화/그래프 표시 | V10: 축/눈금 표시 | W10: 화면 우측 상단의 Search 버튼과 주기 선택 이 겹침. | X10: 화면 우측 상단의 Search 버튼과 주기 선택 이 겹침. 화면을 축소하면.. 화면이 더 일그러짐.. | AA10: 차트 공통 컴포넌트 점검, 무데이터 처리 및 축/범례 표준화
A11: UT-GO12507S | B11: 2-1차 | C11: 1 | D11: 공항운영(GO) | E11: DEF-00197 | F11: Search로는 동작하지만 최초 load시 서버 오류입니다. 관리자에게 문의하세요 발생 | G11: 개발자테스트 | H11: 신문호 | I11: 김경준 | J11: 3자테스터공통 | K11: Online | L11: 결함 | M11: 기능 | N11: 결함검토요청 | O11: 신문호 | P11: Minor | Q11: 결함검토요청 | R11: 46139.606 | S11: 46139.606 | U11: 조회 조건/검색 결과 불일치 | V11: 조회 조건 처리 | W11: Search로는 동작하지만 최초 load시 서버 오류입니다. 관리자에게 문의하세요 발생 | X11: Search로는 동작하지만 최초 load시 서버 오류입니다. 관리자에게 문의하세요 발생 | AA11: 조회 SQL/조건 매핑 재검토, 정렬·필터 기본값 정의서와 일치화
A12: UT-GO11961S | B12: 2-2차 | C12: 1 | D12: 공항운영(GO) | E12: DEF-00253 | F12: 날짜가 9999-01-01 ~ 9999-02-01 이여도 데이터가 표출됨 | G12: 개발자테스트 | H12: 신문호 | I12: 신문호 | J12: 3자테스터공통 | K12: Online | L12: 결함 | M12: 데이터 | N12: 결함검토요청 | O12: 신문호 | P12: Critical | Q12: 결함검토요청 | R12: 46139.724 | S12: 46139.747 | U12: 날짜/기간 처리 | V12: 날짜 입력 유효성 | W12: 날짜가 9999-01-01 ~ 9999-02-01 이여도 데이터가 표출됨 | X12: 날짜가 9999-01-01 ~ 9999-02-01 이여도 데이터가 표출됨 | AA12: 날짜 컴포넌트 표준화, 기준일자-운항일자 등 필드 매핑 점검 및 기간 가드 추가
A13: UT-GO11963S | B13: 2-2차 | C13: 1 | D13: 공항운영(GO) | E13: DEF-00255 | F13: 월간 실적 조회 간 날짜를 종료일자 날짜를 지정하지 않아도 검색이 가능함 | G13: 개발자테스트 | H13: 신문호 | I13: 신문호 | J13: 3자테스터공통 | K13: Online | L13: 결함 | M13: 기능 | N13: 결함검토요청 | O13: 신문호 | P13: Critical | Q13: 결함검토요청 | R13: 46139.728 | S13: 46139.728 | U13: 날짜/기간 처리 | V13: 기간 범위 처리 | W13: 월간 실적 조회 간 날짜를 종료일자 날짜를 지정하지 않아도 검색이 가능함 | X13: 월간 실적 조회 간 날짜를 종료일자 날짜를 지정하지 않아도 검색이 가능함 | AA13: 날짜 컴포넌트 표준화, 기준일자-운항일자 등 필드 매핑 점검 및 기간 가드 추가
... A354: UT-GO12516S | B354: 2-2차 | C354: 1 | D354: 공항운영(GO) | E354: DEF-00181 | F354: 메뉴 최초 들어갔을떄와 초기화 버튼 클릭시 서버 오류입니다 발생합니다 | G354: 개발자테스트 | H354: 신문호 | I354: 김경준 | J354: 3자테스터공통 | K354: Online | L354: 결함 | M354: 기능 | N354: 결함검토요청 | O354: 신문호 | P354: Major | Q354: 결함검토요청 | R354: 46139.569 | S354: 46140.464 | U354: 상태값/버튼 동작 | V354: 버튼 동작 오류 | W354: 메뉴 최초 들어갔을떄와 초기화 버튼 클릭시 서버 오류입니다 발생합니다 | X354: 메뉴 최초 들어갔을떄와 초기화 버튼 클릭시 서버 오류입니다 발생합니다 | AA354: 버튼/상태 컴포넌트 표준 적용, 활성·비활성 조건 명세화
A355: UT-PM20155S | B355: 2-1차 | C355: 1 | D355: 예측관리(PM) | E355: DEF-00224 | F355: 엑셀이 저장 1회 이상은 되지 않습니다. - 엑셀 저장 2번째 > 우측 그래프 활성화 , 엑셀저장 안됨 | G355: 개발자테스트 | H355: 임소정 | I355: 노세찬 | J355: 3자테스터공통 | K355: Online | L355: 결함 | M355: 기능 | N355: 결함등록기각 | P355: Major | Q355: 결함등록기각 | R355: 46139.699 | S355: 46141.36 | T355: 처리완료하였습니다. 개발서버 기준 (26년 04월 30일 오전에 확인가능합니다.) DEF-00222 결함과 같은 내용이므로 기각합니다. | U355: 다운로드/출력 | V355: 엑셀 다운로드 오류 | W355: 엑셀이 저장 1회 이상은 되지 않습니다. | X355: 엑셀이 저장 1회 이상은 되지 않습니다. - 엑셀 저장 2번째 > 우측 그래프 활성화 , 엑셀저장 안됨 | Y355: 기각사유: 처리완료하였습니다. 개발서버 기준 (26년 04월 30일 오전에 확인가능합니다.) DEF-00222 결함과 같은 내용이므로… → 기타 기각 성격으로 판단 | Z355: 기타 기각 | AA355: 엑셀/PDF 공통 출력 모듈 점검, 컬럼 매핑·서식 검증 및 예외 처리
A356: UT-PM10205S | B356: 2-3차 | C356: 1 | D356: 예측관리(PM) | E356: DEF-00271 | F356: 테스트 결과서 없음. | G356: 개발자테스트 | H356: 임소정 | I356: 양우상 | J356: 3자테스터공통 | K356: Online | L356: 결함 | M356: 문서화 | N356: 결함등록기각 | P356: Critical | Q356: 결함등록기각 | R356: 46140.404 | S356: 46141.317 | T356: UT-PM10201S 입국장 운영시간 설정 관리 UT-PM10202S 입국장 운영시간 조회 UT-PM10203S 출국장 운영시간 설정 관리 UT-PM10204S 출국장 운영시간 조회 UT-PM10205S 환승장 운영시간 설정 관리 UT-PM10206S 환승장 운영시간 조회 메뉴들은 UT-PM10201S 운영시간설정관리, UT-PM10202S 운영시간조회 메뉴로 통합되었습니다. | U356: 기타 | V356: 기타 검토 | W356: 테스트 결과서 없음. | X356: 테스트 결과서 없음. | Y356: 기각사유: UT-PM10201S 입국장 운영시간 설정 관리 UT-PM10202S 입국장 운영시간 조회 UT-PM10203S 출국장 운… → 기타 기각 성격으로 판단 | Z356: 기타 기각 | AA356: 담당 PL과 결함 성격 재정의 후 분류 보완
A357: UT-GO11101S | B357: 1-2차 | C357: 1 | D357: 공항운영(GO) | E357: DEF-00273 | F357: 다른 페이지에서는 버튼이 '저장' 입니다. (통일성) | G357: 개발자테스트 | H357: 신문호 | I357: 김경준 | J357: 3자테스터공통 | K357: Online | L357: 개선/변경 | M357: UI | N357: 결함등록기각 | P357: Minor | Q357: 결함등록기각 | R357: 46140.41 | S357: 46142.605 | T357: 둘다 표준 버튼입니다. | U357: 상태값/버튼 동작 | V357: 상태값 처리 | W357: 다른 페이지에서는 버튼이 '저장' 입니다. (통일성) | X357: 다른 페이지에서는 버튼이 '저장' 입니다. (통일성) | Y357: 기각사유: 둘다 표준 버튼입니다. → 기타 기각 성격으로 판단 | Z357: 기타 기각 | AA357: 버튼/상태 컴포넌트 표준 적용, 활성·비활성 조건 명세화
A358: UT-GO11101S | B358: 1-2차 | C358: 1 | D358: 공항운영(GO) | E358: DEF-00277 | F358: 영원히 조회되지 않습니다.. 2026-04-28 10:00 | G358: 개발자테스트 | H358: 신문호 | I358: 김경준 | J358: 3자테스터공통 | K358: Online | L358: 개선/변경 | M358: 기타 | N358: 결함등록기각 | P358: Major | Q358: 결함등록기각 | R358: 46140.417 | S358: 46142.612 | T358: 정상작동중 | U358: 조회 조건/검색 결과 불일치 | V358: 조회 조건 처리 | W358: 영원히 조회되지 않습니다.. 2026-04-28 10:00 | X358: 영원히 조회되지 않습니다.. 2026-04-28 10:00 | Y358: 기각사유: 정상작동중 → 정상동작/스펙대로 성격으로 판단 | Z358: 정상동작/스펙대로 | AA358: 조회 SQL/조건 매핑 재검토, 정렬·필터 기본값 정의서와 일치화
A359: UT-PM20157S | B359: 2-2차 | C359: 1 | D359: 예측관리(PM) | E359: DEF-00309 | F359: 기준일자 선택이 필수 입력이 조건이 아님. 필수여야 할거 같음. | G359: 개발자테스트 | H359: 임소정 | I359: 노세찬 | J359: 3자테스터공통 | K359: Online | L359: 개선/변경 | M359: 기능 | N359: 결함등록기각 | P359: Minor | Q359: 결함등록기각 | R359: 46140.545 | S359: 46141.401 | T359: 처리완료하였습니다. 개발서버 기준 (26년 04월 30일 오전에 확인가능합니다.) DEF-00307 결함과 같은 내용이므로 기각합니다. | U359: 날짜/기간 처리 | V359: 기준일자/조회일자 불일치 | W359: 기준일자 선택이 필수 입력이 조건이 아님. 필수여야 할거 같음. | X359: 기준일자 선택이 필수 입력이 조건이 아님. 필수여야 할거 같음. | Y359: 기각사유: 처리완료하였습니다. 개발서버 기준 (26년 04월 30일 오전에 확인가능합니다.) DEF-00307 결함과 같은 내용이므로… → 기타 기각 성격으로 판단 | Z359: 기타 기각 | AA359: 날짜 컴포넌트 표준화, 기준일자-운항일자 등 필드 매핑 점검 및 기간 가드 추가
A360: UT-CASY011S(A) | B360: 2-2차 | C360: 1 | D360: 공통관리(AOMS-CA) | E360: DEF-00396 | F360: 1. 시나리오-순번1- 관리자 로그인을 위한 ID/PW 입력화면 확인 안됨. 입력없이 좌측에 “조직도선택”이 확인됨. 2. 초기화버튼을 눌렀지만, 그림과 같이 선택된 행들이 선택해제가 되지 않음 3. SMS 전송 현황(상세)-조회기간 10일 제약(시나리오 순번31) 위반 4. 시나리오 순번 39번 관련 조회결과가 없는 경우 경고메시지 표출되지 않음. 5. 전송대상자를 지우고 전송시작을 실행했는데, 실행되버림 | G360: 개발자테스트 | H360: 김명준 | I360: 정연준 | J360: 3자테스터공통 | K360: Online | L360: 개선/변경 | M360: UI | N360: 결함등록기각 | P360: Minor | Q360: 결함등록기각 | R360: 46140.7 | S360: 46142.375 | T360: 로그인 -> CA 모듈 선택 -> 좌측 메뉴 SMS 관리 메뉴를 선택-> 조직도 확인하는 시나리오로 정상입니다 | U360: 시각화/그래프 표시 | V360: 차트 표시 오류 | W360: 1. 시나리오-순번1- 관리자 로그인을 위한 ID/PW 입력화면 확인 안됨. 입력없이 좌측에 “조직도선택… | X360: 1. 시나리오-순번1- 관리자 로그인을 위한 ID/PW 입력화면 확인 안됨. 입력없이 좌측에 “조직도선택”이 확인됨. 2. 초기화버튼을 눌렀지만, 그림과 같이 선택된 행들이 선택해제가 되지 않음 3. SMS 전송 현황(상세)-조회기간 10일 제약(… | Y360: 기각사유: 로그인 -> CA 모듈 선택 -> 좌측 메뉴 SMS 관리 메뉴를 선택-> 조직도 확인하는 시나리오로 정상입니다 → 정상동작/스펙대로 성격으로 판단 | Z360: 정상동작/스펙대로 | AA360: 차트 공통 컴포넌트 점검, 무데이터 처리 및 축/범례 표준화
A361: UT-CASY047S(A) | B361: 2-2차 | C361: 1 | D361: 공통관리(AOMS-CA) | E361: DEF-00412 | F361: 1. 최대조회기간 제한(8일) 위반(시나리오 순번3 관련 화면) | G361: 개발자테스트 | H361: 김명준 | I361: 최민지 | J361: 3자테스터공통 | K361: Online | L361: 개선/변경 | M361: UI | N361: 결함등록기각 | P361: Minor | Q361: 결함등록기각 | R361: 46140.736 | S361: 46142.443 | T361: 단위테스트 후 공항공사 요청으로 검색 기간 변경함 정상입니다. | U361: 날짜/기간 처리 | V361: 기간 범위 처리 | W361: 1. 최대조회기간 제한(8일) 위반(시나리오 순번3 관련 화면) | X361: 1. 최대조회기간 제한(8일) 위반(시나리오 순번3 관련 화면) | Y361: 기각사유: 단위테스트 후 공항공사 요청으로 검색 기간 변경함 정상입니다. → 정상동작/스펙대로 성격으로 판단 | Z361: 정상동작/스펙대로 | AA361: 날짜 컴포넌트 표준화, 기준일자-운항일자 등 필드 매핑 점검 및 기간 가드 추가
A362: UT-CARF037S(A) | B362: 1-1차 | C362: 1 | D362: 공통관리(AOMS-CA) | E362: DEF-00486 | F362: 코드리스트나, 코드 종류에 신규추가,삭제 +,- 버튼이 없음 권한문제로 막혀있나요? | G362: 개발자테스트 | H362: 김명준 | I362: 김태훈 | J362: 3자테스터공통 | K362: Online | L362: 결함 | M362: UI | N362: 결함등록기각 | P362: Minor | Q362: 결함등록기각 | R362: 46141.62 | S362: 46142.558 | T362: 동일 건으로 공항공사 요청사항 수정중이로 결함등록기각 으로 변경하겠습니다. | U362: 상태값/버튼 동작 | V362: 상태값 처리 | W362: 코드리스트나, 코드 종류에 신규추가,삭제 +,- 버튼이 없음 | X362: 코드리스트나, 코드 종류에 신규추가,삭제 +,- 버튼이 없음 권한문제로 막혀있나요? | Y362: 기각사유: 동일 건으로 공항공사 요청사항 수정중이로 결함등록기각 으로 변경하겠습니다. → 중복 성격으로 판단 | Z362: 중복 | AA362: 버튼/상태 컴포넌트 표준 적용, 활성·비활성 조건 명세화
A363: UT-FSSG170S | B363: 2-2차 | C363: 1 | D363: 항공보안(FS) | E363: DEF-00498 | F363: 창을 줄이면 업무처리실적리스트에 가로스크롤이 생기지 않습니다. | G363: 개발자테스트 | H363: 임소정 | I363: 임소정 | J363: 3자테스터공통 | K363: Online | L363: 개선/변경 | M363: UI | N363: 결함등록기각 | P363: Minor | Q363: 결함등록기각 | R363: 46141.645 | S363: 46149.819 | T363: 전체화면 기준으로 개발 되었으며 넥사크로는 컴포넌트별로 위치나 크기등의 설정을 하므로 창 너비에 따른 개발이 어려움. | U363: 개선요청/정책반영 | V363: 개선/변경 요청 | W363: 창을 줄이면 업무처리실적리스트에 가로스크롤이 생기지 않습니다. | X363: 창을 줄이면 업무처리실적리스트에 가로스크롤이 생기지 않습니다. | Y363: 기각사유: 전체화면 기준으로 개발 되었으며 넥사크로는 컴포넌트별로 위치나 크기등의 설정을 하므로 창 너비에 따른 개발이 어려움. → 기타 기각 성격으로 판단 | Z363: 기타 기각 | AA363: 차기 반영 일감으로 등록 후 우선순위 협의, 정책 가이드 반영
A364: UT-CASY033S(A) | B364: 1-1차 | C364: 1 | D364: 공통관리(AOMS-CA) | E364: DEF-00513 | F364: 화면배율을 크게하면 체크박스가 넘어감 | G364: 개발자테스트 | H364: 김명준 | I364: 최민지 | J364: 3자테스터공통 | K364: Online | L364: 결함 | M364: UI | N364: 결함등록기각 | P364: Minor | Q364: 결함등록기각 | R364: 46141.671 | S364: 46142.431 | T364: 공통 퍼블로 퍼블 담당자에게 전달 하겠습니다. | U364: 상태값/버튼 동작 | V364: 선택/체크 동작 | W364: 화면배율을 크게하면 체크박스가 넘어감 | X364: 화면배율을 크게하면 체크박스가 넘어감 | Y364: 기각사유: 공통 퍼블로 퍼블 담당자에게 전달 하겠습니다. → 기타 기각 성격으로 판단 | Z364: 기타 기각 | AA364: 버튼/상태 컴포넌트 표준 적용, 활성·비활성 조건 명세화
A365: UT-FSSG170S | B365: 2-2차 | C365: 1 | D365: 항공보안(FS) | E365: DEF-00514 | F365: 오타가 있습니다. | G365: 개발자테스트 | H365: 임소정 | I365: 임소정 | J365: 3자테스터공통 | K365: Online | L365: 개선/변경 | M365: 데이터 | N365: 결함등록기각 | P365: Minor | Q365: 결함등록기각 | R365: 46141.671 | S365: 46148.676 | T365: 오타가 아닌 공통코드에 저장된 데이터임. | U365: 용어/라벨/문구 | V365: 오타 | W365: 오타가 있습니다. | X365: 오타가 있습니다. | Y365: 기각사유: 오타가 아닌 공통코드에 저장된 데이터임. → 기타 기각 성격으로 판단 | Z365: 기타 기각 | AA365: 용어집 기준으로 라벨 일괄 정비, 오타/표기 표준 적용
A366: UT-CAMN012M(A) | B366: 1-1차 | C366: 1 | D366: 공통관리(AOMS-CA) | E366: DEF-00522 | F366: 프로그램 사용 사유 등록 팝업은 어디서 확인할수 있나요..? | G366: 개발자테스트 | H366: 김명준 | I366: 정연준 | J366: 3자테스터공통 | K366: Online | L366: 결함 | M366: 인터페이스 | N366: 결함등록기각 | P366: Minor | Q366: 결함등록기각 | R366: 46141.706 | S366: 46141.788 | T366: 단위 시험 이후 타 모듈에서 사용하는 팝업으로 해당 모듈에서 가능합니다. | U366: 메시지/가이드 부족 | V366: 메시지 표시 | W366: 프로그램 사용 사유 등록 팝업은 어디서 확인할수 있나요..? | X366: 프로그램 사용 사유 등록 팝업은 어디서 확인할수 있나요..? | Y366: 기각사유: 단위 시험 이후 타 모듈에서 사용하는 팝업으로 해당 모듈에서 가능합니다. → 기타 기각 성격으로 판단 | Z366: 기타 기각 | AA366: UX 가이드라인에 따라 표준 안내·툴팁 문구 적용, 무데이터/오류 메시지 정비
... A571: UT-PM20156S | B571: 2-2차 | C571: 1 | D571: 예측관리(PM) | E571: DEF-00422 | F571: 엑셀저장 버튼 클릭시 그래프 비교 화면이 나타남.(엑셀파일은 저장 안됨) | G571: 개발자테스트 | H571: 임소정 | I571: 노세찬 | J571: 3자테스터공통 | K571: Online | L571: 결함 | M571: 기능 | N571: 결함등록기각 | P571: Major | Q571: 결함등록기각 | R571: 46140.753 | S571: 46141.36 | T571: 처리완료하였습니다. 개발서버 기준 (26년 04월 30일 오전에 확인가능합니다.) DEF-00222 결함과 같은 내용이므로 기각합니다. | U571: 다운로드/출력 | V571: 엑셀 다운로드 오류 | W571: 엑셀저장 버튼 클릭시 그래프 비교 화면이 나타남.(엑셀파일은 저장 안됨) | X571: 엑셀저장 버튼 클릭시 그래프 비교 화면이 나타남.(엑셀파일은 저장 안됨) | Y571: 기각사유: 처리완료하였습니다. 개발서버 기준 (26년 04월 30일 오전에 확인가능합니다.) DEF-00222 결함과 같은 내용이므로… → 기타 기각 성격으로 판단 | Z571: 기타 기각 | AA571: 엑셀/PDF 공통 출력 모듈 점검, 컬럼 매핑·서식 검증 및 예외 처리
A572: UT-FSEX020S | B572: 2-1차 | C572: 1 | D572: 항공보안(FS) | E572: DEF-00509 | F572: 수정버튼을 눌러야 체크되어 있는 것이 보임. | G572: 개발자테스트 | H572: 임소정 | I572: 임소정 | J572: 3자테스터공통 | K572: Online | L572: 결함 | M572: 기능 | N572: 조치요청 | O572: 임소정 | P572: Major | Q572: 조치요청 | R572: 46141.665 | S572: 46150.363 | U572: 상태값/버튼 동작 | V572: 버튼 동작 오류 | W572: 수정버튼을 눌러야 체크되어 있는 것이 보임. | X572: 수정버튼을 눌러야 체크되어 있는 것이 보임. | AA572: 버튼/상태 컴포넌트 표준 적용, 활성·비활성 조건 명세화
A573: UT-FSEX021S | B573: 2-2차 | C573: 1 | D573: 항공보안(FS) | E573: DEF-00122 | F573: -페이지번호 누락 -MS-WORD파일 출력 에러(용지크기 오류, 출력대상 오류) -엑셀파일 출력(용지 확인, 1페이지-> 2페이지 조정) -다운로드받은 각 파일들 왼쪽에 쏠림현상(출력대상 내용이 많지만, 좌우 여백 고려할 필요->관련 기능이 있다면 좌측여백 조정 지원 필요) -AOMS화면 프린터 클릭 출력후 화면에서 출력내용 없음. | G573: 개발자테스트 | H573: 임소정 | I573: 임소정 | J573: 3자테스터공통 | K573: Online | L573: 개선/변경 | M573: UI | N573: 조치요청 | O573: 임소정 | P573: Minor | Q573: 조치요청 | R573: 46136.445 | S573: 46141.667 | U573: 다운로드/출력 | V573: 엑셀 다운로드 오류 | W573: -페이지번호 누락 | X573: -페이지번호 누락 -MS-WORD파일 출력 에러(용지크기 오류, 출력대상 오류) -엑셀파일 출력(용지 확인, 1페이지-> 2페이지 조정) -다운로드받은 각 파일들 왼쪽에 쏠림현상(출력대상 내용이 많지만, 좌우 여백 고려할 필요->관련 기능이 있다면… | AA573: 엑셀/PDF 공통 출력 모듈 점검, 컬럼 매핑·서식 검증 및 예외 처리
A574: UT-FSEX019S | B574: 2-2차 | C574: 1 | D574: 항공보안(FS) | E574: DEF-00113 | F574: -페이지 하단 페이지 번호 누락 -다운로드받은 엑셀파일 출력 용지 방향을 세로로 설정 필요(1페이지가 2페이지로 출력됨) -AOMS화면내 출력내용의 왼편으로 쏠림(셀크기 조정 기능이 있다면 적용 필요) -AOMS화면내 프린터 클릭후 출력내용이 안 보임. -AOMS 화면내 시기 선택 관련 다른 화면과 상이(다만, 본 화면은 년/월 선택조건) | G574: 개발자테스트 | H574: 임소정 | I574: 임소정 | J574: 3자테스터공통 | K574: Online | L574: 개선/변경 | M574: UI | N574: 조치요청 | O574: 임소정 | P574: Minor | Q574: 조치요청 | R574: 46136.401 | S574: 46141.667 | U574: 다운로드/출력 | V574: 엑셀 다운로드 오류 | W574: -페이지 하단 페이지 번호 누락 | X574: -페이지 하단 페이지 번호 누락 -다운로드받은 엑셀파일 출력 용지 방향을 세로로 설정 필요(1페이지가 2페이지로 출력됨) -AOMS화면내 출력내용의 왼편으로 쏠림(셀크기 조정 기능이 있다면 적용 필요) -AOMS화면내 프린터 클릭후 출력내용이 안 … | AA574: 엑셀/PDF 공통 출력 모듈 점검, 컬럼 매핑·서식 검증 및 예외 처리
A575: UT-CASY001S(A) | B575: 1-1차 | C575: 1 | D575: 공통관리(AOMS-CA) | E575: DEF-00144 | F575: 보여지는 Message List에는 없지만 데이터는 있을 경우 중복데이터 오류메시지가 아닌 서버오류 메시지가 나옵니다. | G575: 개발자테스트 | H575: 김명준 | I575: 정연준 | J575: 3자테스터공통 | K575: Online | L575: 개선/변경 | M575: 데이터 | N575: 최종확인 | P575: Minor | Q575: 최종확인 | R575: 46136.663 | S575: 46141.684 | U575: 메시지/가이드 부족 | V575: 안내 메시지 부재 | W575: 보여지는 Message List에는 없지만 데이터는 있을 경우 중복데이터 오류메시지가 아닌 서버오류 메시… | X575: 보여지는 Message List에는 없지만 데이터는 있을 경우 중복데이터 오류메시지가 아닌 서버오류 메시지가 나옵니다. | AA575: UX 가이드라인에 따라 표준 안내·툴팁 문구 적용, 무데이터/오류 메시지 정비
A576: UT-CASY014S(A) | B576: 1-1차 | C576: 1 | D576: 공통관리(AOMS-CA) | E576: DEF-00150 | F576: 보여지는 List에는 없지만 데이터는 있을 경우 중복데이터 오류메시지가 아닌 서버오류 메시지가 나옵니다. 데이터 조회기능과 생성기능이 같이있는 페이지 경우 같은 오류가 나옵니다. 이 이후 생기는 페이지는 결함으로 올리지 않겠습니다. 같은 종류의 페이지 확인 부탁드립니다. | G576: 개발자테스트 | H576: 김명준 | I576: 최민지 | J576: 3자테스터공통 | K576: Online | L576: 결함 | M576: 데이터 | N576: 최종확인 | P576: Minor | Q576: 최종확인 | R576: 46136.709 | S576: 46142.431 | U576: 조회 조건/검색 결과 불일치 | V576: 조회 조건 처리 | W576: 보여지는 List에는 없지만 데이터는 있을 경우 중복데이터 오류메시지가 아닌 서버오류 메시지가 나옵니다. | X576: 보여지는 List에는 없지만 데이터는 있을 경우 중복데이터 오류메시지가 아닌 서버오류 메시지가 나옵니다. 데이터 조회기능과 생성기능이 같이있는 페이지 경우 같은 오류가 나옵니다. 이 이후 생기는 페이지는 결함으로 올리지 않겠습니다. 같은 종류의 … | AA576: 조회 SQL/조건 매핑 재검토, 정렬·필터 기본값 정의서와 일치화
A577: UT-CASY006S(A) | B577: 1-2차 | C577: 1 | D577: 공통관리(AOMS-CA) | E577: DEF-00380 | F577: 아래의 첫화면에서 아래로 스크롤하면.. 내용만 스크롤 되지 않고.. 화면 전체가 올라가서.. 상단 Search 버튼은 사라지고.. 하단의 Save 버튼은 함께 따라 올라옴 | G577: 개발자테스트 | H577: 김명준 | I577: 정연준 | J577: 3자테스터공통 | K577: Online | L577: 결함 | M577: UI | N577: 최종확인 | P577: Minor | Q577: 최종확인 | R577: 46140.651 | S577: 46141.557 | U577: 조회 조건/검색 결과 불일치 | V577: 조회 조건 처리 | W577: 아래의 첫화면에서 아래로 스크롤하면.. 내용만 스크롤 되지 않고.. 화면 전체가 올라가서.. 상단 Sea… | X577: 아래의 첫화면에서 아래로 스크롤하면.. 내용만 스크롤 되지 않고.. 화면 전체가 올라가서.. 상단 Search 버튼은 사라지고.. 하단의 Save 버튼은 함께 따라 올라옴 | AA577: 조회 SQL/조건 매핑 재검토, 정렬·필터 기본값 정의서와 일치화
A578: UT-CAMN002M(A) | B578: 1-2차 | C578: 1 | D578: 공통관리(AOMS-CA) | E578: DEF-00096 | F578: 로그인중 OTP 인증 불가로 테스트 진행 불가 | G578: 개발자테스트 | H578: 김명준 | I578: 정연준 | J578: 3자테스터공통 | K578: Online | L578: 개선/변경 | M578: UI | N578: 최종확인 | P578: Minor | Q578: 최종확인 | R578: 46135.639 | S578: 46142.42 | U578: 권한/접근/노출 | V578: 권한/노출 제어 | W578: 로그인중 OTP 인증 불가로 테스트 진행 불가 | X578: 로그인중 OTP 인증 불가로 테스트 진행 불가 | AA578: 권한 매트릭스 재확인, 메뉴/버튼 노출 규칙 일치화
A579: UT-CASY010S(A) | B579: 1-2차 | C579: 1 | D579: 공통관리(AOMS-CA) | E579: DEF-00125 | F579: 검색창에서 검색을 하지 않은 상태에서는 중복데이터 알림이 나오지만 검색 후 추가를 하면 아래 이미지와 같은 오류메시지가 나옵니다. | G579: 개발자테스트 | H579: 김명준 | I579: 최민지 | J579: 3자테스터공통 | K579: Online | L579: 개선/변경 | M579: UI | N579: 최종확인 | P579: Minor | Q579: 최종확인 | R579: 46136.474 | S579: 46141.421 | U579: 조회 조건/검색 결과 불일치 | V579: 조회 조건 처리 | W579: 검색창에서 검색을 하지 않은 상태에서는 중복데이터 알림이 나오지만 | X579: 검색창에서 검색을 하지 않은 상태에서는 중복데이터 알림이 나오지만 검색 후 추가를 하면 아래 이미지와 같은 오류메시지가 나옵니다. | AA579: 조회 SQL/조건 매핑 재검토, 정렬·필터 기본값 정의서와 일치화
A580: UT-CARF037S(A) | B580: 1-1차 | C580: 1 | D580: 공통관리(AOMS-CA) | E580: DEF-00265 | F580: 공통코드관리 에 해당하는 메뉴를 찾을 수 없습니다. 영문 메뉴 경로 필요. | G580: 개발자테스트 | H580: 김명준 | I580: 김태훈 | J580: 3자테스터공통 | K580: Online | L580: 결함 | M580: 기능 | N580: 최종확인 | P580: Major | Q580: 최종확인 | R580: 46139.742 | S580: 46141.606 | U580: 입력 검증/유효성 | V580: 입력 문자 제한 | W580: 공통코드관리 에 해당하는 메뉴를 찾을 수 없습니다. | X580: 공통코드관리 에 해당하는 메뉴를 찾을 수 없습니다. 영문 메뉴 경로 필요. | AA580: 프론트/백엔드 양측에 입력 유효성 검증 추가 및 공통 validator 적용
A581: UT-PM10103S | B581: 2-1차 | C581: 1 | D581: 예측관리(PM) | E581: DEF-00235 | F581: 화면의 첫 째 필드에 커셔가 Set focus되어 있지 않음. | G581: 개발자테스트 | H581: 임소정 | I581: pmtbd2 | J581: 3자테스터공통 | K581: Online | L581: 개선/변경 | M581: UI | N581: 최종확인 | P581: Minor | Q581: 최종확인 | R581: 46139.718 | S581: 46148.745 | U581: 개선요청/정책반영 | V581: 개선/변경 요청 | W581: 화면의 첫 째 필드에 커셔가 Set focus되어 있지 않음. | X581: 화면의 첫 째 필드에 커셔가 Set focus되어 있지 않음. | AA581: 차기 반영 일감으로 등록 후 우선순위 협의, 정책 가이드 반영
A582: UT-CAMN015M(A) | B582: 1-1차 | C582: 1 | D582: 공통관리(AOMS-CA) | E582: DEF-00230 | F582: 파일첨부 팝업 메뉴를 찾을 수가 없음. | G582: 개발자테스트 | H582: 김명준 | I582: 정연준 | J582: 3자테스터공통 | K582: Online | L582: 결함 | M582: 기능 | N582: 최종확인 | P582: Major | Q582: 최종확인 | R582: 46139.712 | S582: 46141.716 | U582: 메시지/가이드 부족 | V582: 안내 메시지 부재 | W582: 파일첨부 팝업 메뉴를 찾을 수가 없음. | X582: 파일첨부 팝업 메뉴를 찾을 수가 없음. | AA582: UX 가이드라인에 따라 표준 안내·툴팁 문구 적용, 무데이터/오류 메시지 정비
A583: UT-CAMN014M(A) | B583: 1-1차 | C583: 1 | D583: 공통관리(AOMS-CA) | E583: DEF-00523 | F583: Company Type readonly로 막아놓을꺼면 빈칸으로 남겨두거나, 삭제하면 좋을것 같습니다 | G583: 개발자테스트 | H583: 김명준 | I583: 정연준 | J583: 3자테스터공통 | K583: Online | L583: 개선/변경 | M583: 기능 | N583: 확인요청 | O583: 3자테스터공통 | P583: Minor | Q583: 확인대기 | R583: 46141.714 | S583: 46148.392 | U583: 개선요청/정책반영 | V583: 개선/변경 요청 | W583: Company Type readonly로 막아놓을꺼면 빈칸으로 남겨두거나, 삭제하면 좋을것 같습니다 | X583: Company Type readonly로 막아놓을꺼면 빈칸으로 남겨두거나, 삭제하면 좋을것 같습니다 | AA583: 차기 반영 일감으로 등록 후 우선순위 협의, 정책 가이드 반영
A584: UT-CASY002S(A) | B584: 1-1차 | C584: 1 | D584: 공통관리(AOMS-CA) | E584: DEF-00528 | F584: program descripton validator 걸렸을때 undefined의 길이라고 뜹니다 | G584: 개발자테스트 | H584: 김명준 | I584: 정연준 | J584: 3자테스터공통 | K584: Online | L584: 결함 | M584: UI | N584: 확인요청 | O584: 3자테스터공통 | P584: Minor | Q584: 확인대기 | R584: 46141.742 | S584: 46148.393 | U584: 입력 검증/유효성 | V584: 입력값 유효성 | W584: program descripton validator 걸렸을때 undefined의 길이라고 뜹니다 | X584: program descripton validator 걸렸을때 undefined의 길이라고 뜹니다 | AA584: 프론트/백엔드 양측에 입력 유효성 검증 추가 및 공통 validator 적용
...

Sheet 분석요약
A1: 결함 분석 요약
A3: 1. 결함패턴_대분류별 건수 | D3: 2. 기각사유_분류별 건수
A4: 대분류 | B4: 건수 | C4: 비율 | D4: 기각분류 | E4: 건수 | F4: 비율
A5: 입력 검증/유효성 | B5: =COUNTIF('UIUX 점검'!U:U,A5) -> 34 | C5: =IFERROR(B5/SUM(B$5:B$19),0) -> 0.051987768 | D5: 중복 | E5: =COUNTIF('UIUX 점검'!Z:Z,D5) -> 16 | F5: =IFERROR(E5/SUM(E$5:E$13),0) -> 0.073059361
A6: 날짜/기간 처리 | B6: =COUNTIF('UIUX 점검'!U:U,A6) -> 93 | C6: =IFERROR(B6/SUM(B$5:B$19),0) -> 0.14220183 | D6: 오등록/테스터오류 | E6: =COUNTIF('UIUX 점검'!Z:Z,D6) -> 0 | F6: =IFERROR(E6/SUM(E$5:E$13),0) -> 0
A7: 조회 조건/검색 결과 불일치 | B7: =COUNTIF('UIUX 점검'!U:U,A7) -> 110 | C7: =IFERROR(B7/SUM(B$5:B$19),0) -> 0.16819572 | D7: 정상동작/스펙대로 | E7: =COUNTIF('UIUX 점검'!Z:Z,D7) -> 63 | F7: =IFERROR(E7/SUM(E$5:E$13),0) -> 0.28767123
A8: 메시지/가이드 부족 | B8: =COUNTIF('UIUX 점검'!U:U,A8) -> 24 | C8: =IFERROR(B8/SUM(B$5:B$19),0) -> 0.036697248 | D8: 요구사항 범위외 | E8: =COUNTIF('UIUX 점검'!Z:Z,D8) -> 0 | F8: =IFERROR(E8/SUM(E$5:E$13),0) -> 0
A9: 시각화/그래프 표시 | B9: =COUNTIF('UIUX 점검'!U:U,A9) -> 38 | C9: =IFERROR(B9/SUM(B$5:B$19),0) -> 0.058103976 | D9: 정책상 비대상 | E9: =COUNTIF('UIUX 점검'!Z:Z,D9) -> 1 | F9: =IFERROR(E9/SUM(E$5:E$13),0) -> 0.00456621
A10: 다운로드/출력 | B10: =COUNTIF('UIUX 점검'!U:U,A10) -> 97 | C10: =IFERROR(B10/SUM(B$5:B$19),0) -> 0.14831804 | D10: 재현불가 | E10: =COUNTIF('UIUX 점검'!Z:Z,D10) -> 0 | F10: =IFERROR(E10/SUM(E$5:E$13),0) -> 0
A11: 용어/라벨/문구 | B11: =COUNTIF('UIUX 점검'!U:U,A11) -> 11 | C11: =IFERROR(B11/SUM(B$5:B$19),0) -> 0.016819572 | D11: 개선요청 이관 | E11: =COUNTIF('UIUX 점검'!Z:Z,D11) -> 6 | F11: =IFERROR(E11/SUM(E$5:E$13),0) -> 0.02739726
A12: 화면 레이아웃/정렬/가독성 | B12: =COUNTIF('UIUX 점검'!U:U,A12) -> 30 | C12: =IFERROR(B12/SUM(B$5:B$19),0) -> 0.04587156 | D12: 협의/보류 | E12: =COUNTIF('UIUX 점검'!Z:Z,D12) -> 3 | F12: =IFERROR(E12/SUM(E$5:E$13),0) -> 0.01369863
A13: 상태값/버튼 동작 | B13: =COUNTIF('UIUX 점검'!U:U,A13) -> 45 | C13: =IFERROR(B13/SUM(B$5:B$19),0) -> 0.068807339 | D13: 기타 기각 | E13: =COUNTIF('UIUX 점검'!Z:Z,D13) -> 130 | F13: =IFERROR(E13/SUM(E$5:E$13),0) -> 0.59360731
A14: 예외처리/오류 대응 | B14: =COUNTIF('UIUX 점검'!U:U,A14) -> 11 | C14: =IFERROR(B14/SUM(B$5:B$19),0) -> 0.016819572 | D14: 합계 | E14: =SUM(E5:E13) -> 219 | F14: =SUM(F5:F13) -> 1
A15: 권한/접근/노출 | B15: =COUNTIF('UIUX 점검'!U:U,A15) -> 7 | C15: =IFERROR(B15/SUM(B$5:B$19),0) -> 0.010703364
A16: 데이터 정합성/매핑 | B16: =COUNTIF('UIUX 점검'!U:U,A16) -> 57 | C16: =IFERROR(B16/SUM(B$5:B$19),0) -> 0.087155963
A17: 문서/요건 불일치 | B17: =COUNTIF('UIUX 점검'!U:U,A17) -> 1 | C17: =IFERROR(B17/SUM(B$5:B$19),0) -> 0.001529052
A18: 개선요청/정책반영 | B18: =COUNTIF('UIUX 점검'!U:U,A18) -> 54 | C18: =IFERROR(B18/SUM(B$5:B$19),0) -> 0.082568807
A19: 기타 | B19: =COUNTIF('UIUX 점검'!U:U,A19) -> 42 | C19: =IFERROR(B19/SUM(B$5:B$19),0) -> 0.064220183
A20: 합계 | B20: =SUM(B5:B19) -> 654 | C20: =SUM(C5:C19) -> 1
A22: 3. 심각도별 주요 패턴 Top 15
A23: 심각도 | B23: 결함패턴_대분류 | C23: 건수
A24: Minor | B24: 조회 조건/검색 결과 불일치 | C24: 76
A25: Minor | B25: 다운로드/출력 | C25: 75
A26: Minor | B26: 날짜/기간 처리 | C26: 69
A27: Minor | B27: 개선요청/정책반영 | C27: 47
A28: Minor | B28: 데이터 정합성/매핑 | C28: 36
A29: Major | B29: 조회 조건/검색 결과 불일치 | C29: 27
A30: Minor | B30: 입력 검증/유효성 | C30: 27
A31: Minor | B31: 화면 레이아웃/정렬/가독성 | C31: 27
A32: Major | B32: 상태값/버튼 동작 | C32: 25
A33: Minor | B33: 시각화/그래프 표시 | C33: 23
A34: Minor | B34: 기타 | C34: 19
A35: Minor | B35: 메시지/가이드 부족 | C35: 18
... A38: Minor | B38: 상태값/버튼 동작 | C38: 16
A41: 4. 업무모듈별 주요 패턴 Top 20
A42: 업무모듈명 | B42: 결함패턴_대분류 | C42: 건수
A43: 공항운영(GO) | B43: 조회 조건/검색 결과 불일치 | C43: 63
A44: 공항운영(GO) | B44: 날짜/기간 처리 | C44: 44
A45: 공항운영(GO) | B45: 다운로드/출력 | C45: 35
A46: 예측관리(PM) | B46: 개선요청/정책반영 | C46: 32
...
