Workbook
Name f_list: Sheet3!$A$5:$E$21
Name lll: Sheet3!$K$47:$Q$63

Sheet Sheet3
A2: 테스트차수 | B2: 2-2차
A3: 단계 | B3: (모두)
A4: 결함상태 | B4: (다중 항목) | L4: 업무 모듈 | M4: 합계 | N4: Critical | O4: Major | P4: Minor
L5: 공항운영(GO) | M5: =VLOOKUP(L5,f_list,5,FALSE) -> 22 | N5: =VLOOKUP(L5,f_list,2,FALSE) -> 8 | O5: =VLOOKUP(L5,f_list,3,FALSE) -> 0 | P5: 210 | Q5: 619 | R5: =VLOOKUP(P5,f_list,2,FALSE) -> #N/A
A6: 개수 : 결함ID | B6: 열 레이블 | L6: 항공기관제(AC) | M6: =VLOOKUP(L6,f_list,5,FALSE) -> 36 | N6: =VLOOKUP(L6,f_list,2,FALSE) -> 3 | O6: 92 | P6: 244 | Q6: 360 | R6: 24
A7: 행 레이블 | B7: 3자테스트 | C7: PL테스트 | D7: 감리테스트 | E7: 공사테스트 | F7: 현업테스트 | G7: 총합계 | L7: 공통관리(FIMS-CA) | M7: =VLOOKUP(L7,f_list,5,FALSE) -> 42 | N7: =VLOOKUP(L7,f_list,2,FALSE) -> 23 | O7: 44 | P7: 291 | Q7: 341 | R7: 6
A8: A-CDM(CM) | B8: 17 | C8: 4 | D8: 38 | E8: 39 | F8: 27 | G8: 125 | L8: 항공보안(FS) | M8: =VLOOKUP(L8,f_list,5,FALSE) -> #N/A | N8: =VLOOKUP(L8,f_list,2,FALSE) -> #N/A | O8: 47 | P8: 275 | Q8: 335 | R8: 13
A9: SLOT관리(SLOT) | B9: 3 | D9: 4 | E9: 7 | G9: 14 | L9: 자원배정(RS) | M9: =VLOOKUP(L9,f_list,5,FALSE) -> 17 | N9: =VLOOKUP(L9,f_list,2,FALSE) -> 17 | O9: 113 | P9: 191 | Q9: 325 | R9: 21
A10: 공통관리(AOMS-CA) | B10: 24 | E10: 14 | G10: 38 | L10: 공통관리(AOMS-CA) | M10: =VLOOKUP(L10,f_list,5,FALSE) -> 14 | N10: =VLOOKUP(L10,f_list,2,FALSE) -> 24 | O10: 32 | P10: 284 | Q10: 319 | R10: 3
A11: 공통관리(FIMS-CA) | B11: 23 | D11: 4 | E11: 42 | F11: 10 | G11: 79 | L11: 운항계획(FP) | M11: =VLOOKUP(L11,f_list,5,FALSE) -> 28 | N11: =VLOOKUP(L11,f_list,2,FALSE) -> 16 | O11: 38 | P11: 260 | Q11: 319 | R11: 21
A12: 공항운영(GO) | B12: 8 | D12: 9 | E12: 22 | F12: 9 | G12: 48 | L12: 모바일(WES) | M12: =VLOOKUP(L12,f_list,5,FALSE) -> 12 | N12: =VLOOKUP(L12,f_list,2,FALSE) -> 3 | O12: 115 | P12: 187 | Q12: 312 | R12: 10
A13: 모바일(MES) | B13: 4 | E13: 48 | F13: 23 | G13: 75 | L13: 모바일(MES) | M13: =VLOOKUP(L13,f_list,5,FALSE) -> 48 | N13: =VLOOKUP(L13,f_list,2,FALSE) -> 4 | O13: 105 | P13: 171 | Q13: 287 | R13: 11
A14: 모바일(WES) | B14: 3 | D14: 5 | E14: 12 | F14: 5 | G14: 25 | L14: 예측관리(PM) | M14: =VLOOKUP(L14,f_list,5,FALSE) -> 19 | N14: =VLOOKUP(L14,f_list,2,FALSE) -> 15 | O14: 84 | P14: 90 | Q14: 208 | R14: 34
A15: 비상계획(CP) | B15: 1 | C15: 2 | E15: 3 | F15: 9 | G15: 15 | L15: A-CDM(CM) | M15: =VLOOKUP(L15,f_list,5,FALSE) -> 39 | N15: =VLOOKUP(L15,f_list,2,FALSE) -> 17 | O15: 92 | P15: 108 | Q15: 206 | R15: 6
A16: 예측관리(PM) | B16: 15 | D16: 11 | E16: 19 | G16: 45 | L16: 항공통계포털(AS) | M16: =VLOOKUP(L16,f_list,5,FALSE) -> #N/A | N16: =VLOOKUP(L16,f_list,2,FALSE) -> #N/A | O16: 83 | P16: 90 | Q16: 200 | R16: 27
A17: 운항계획(FP) | B17: 16 | D17: 1 | E17: 28 | F17: 6 | G17: 51 | L17: SLOT관리(SLOT) | M17: =VLOOKUP(L17,f_list,5,FALSE) -> 7 | N17: =VLOOKUP(L17,f_list,2,FALSE) -> 3 | O17: 42 | P17: 97 | Q17: 166 | R17: 27
A18: 자원배정(RS) | B18: 17 | C18: 7 | D18: 12 | E18: 17 | F18: 10 | G18: 63 | L18: 자원배정차트(RC) | M18: =VLOOKUP(L18,f_list,5,FALSE) -> 7 | N18: =VLOOKUP(L18,f_list,2,FALSE) -> 4 | O18: 41 | P18: 71 | Q18: 145 | R18: 33
A19: 자원배정엔진(RE) | B19: 3 | D19: 2 | E19: 6 | G19: 11 | L19: 비상계획(CP) | M19: =VLOOKUP(L19,f_list,5,FALSE) -> 3 | N19: =VLOOKUP(L19,f_list,2,FALSE) -> 1 | O19: 17 | P19: 22 | Q19: 39 | R19: 0
A20: 자원배정차트(RC) | B20: 4 | D20: 3 | E20: 7 | F20: 2 | G20: 16 | L20: 자원배정엔진(RE) | M20: =VLOOKUP(L20,f_list,5,FALSE) -> 6 | N20: =VLOOKUP(L20,f_list,2,FALSE) -> 3 | O20: 7 | P20: 9 | Q20: 17 | R20: 1
A21: 항공기관제(AC) | B21: 3 | C21: 48 | D21: 1 | E21: 36 | F21: 40 | G21: 128 | L21: 푸시SW(PUSH) | M21: =VLOOKUP(L21,f_list,5,FALSE) -> #N/A | N21: =VLOOKUP(L21,f_list,2,FALSE) -> #N/A | O21: 1 | P21: 3 | Q21: 5 | R21: 1
A22: 항공보안(FS) | B22: 2 | D22: 7 | E22: 31 | F22: 3 | G22: 43 | L22: 합계 | M22: 4203 | N22: 416 | O22: 1113 | P22: 2503
A23: 항공통계포털(AS) | B23: 13 | D23: 42 | E23: 69 | G23: 124
A24: 총합계 | B24: 156 | C24: 61 | D24: 139 | E24: 400 | F24: 144 | G24: 900
A25: 조치상태 | B25: (다중 항목)
A27: 개수 : 결함ID | B27: 열 레이블 | L27: 차수 | M27: 개발자 | N27: PL | O27: 3자 | P27: 공사 | Q27: 현업 | R27: 감리 | S27: 계
A28: 행 레이블 | B28: 3자테스트 | C28: PL테스트 | D28: 감리테스트 | E28: 개발자테스트 | F28: 공사테스트 | G28: 현업테스트 | H28: 총합계 | L28: 1-1차 | M28: 1 | N28: 69 | O28: 8 | P28: 524 | Q28: 101 | R28: 46 | S28: =SUM(M28:R28) -> 749
A29: 1-1차 | B29: 8 | C29: 69 | D29: 46 | E29: 1 | F29: 524 | G29: 101 | H29: 749 | L29: 1-2차 | M29: 1 | N29: 31 | O29: 404 | P29: 530 | Q29: 208 | R29: 79 | S29: =SUM(M29:R29) -> 1253
A30: 1-2차 | B30: 404 | C30: 31 | D30: 79 | E30: 1 | F30: 530 | G30: 208 | H30: 1253 | L30: 2-1차 | M30: - | N30: 21 | O30: 220 | P30: 543 | Q30: 217 | R30: 171 | S30: =SUM(M30:R30) -> 1172
A31: 2-1차 | B31: 220 | C31: 21 | D31: 171 | F31: 543 | G31: 217 | H31: 1172 | L31: 2-2차 | M31: - | N31: 61 | O31: 156 | P31: 400 | Q31: 144 | R31: 139 | S31: =SUM(M31:R31) -> 900
A32: 2-2차 | B32: 156 | C32: 61 | D32: 139 | F32: 400 | G32: 144 | H32: 900 | L32: 2-3차 | M32: - | N32: 24 | O32: 94 | P32: 10 | Q32: 2 | R32: - | S32: =SUM(M32:R32) -> 130
A33: 2-3차 | B33: 94 | C33: 24 | F33: 10 | G33: 2 | H33: 130 | L33: 합계 | M33: 2 | N33: 206 | O33: 882 | P33: 2007 | Q33: 672 | R33: 435 | S33: =SUM(S28:S32) -> 4204
A34: 총합계 | B34: 882 | C34: 206 | D34: 435 | E34: 2 | F34: 2007 | G34: 672 | H34: 4204
K42: 결함구분 | L42: (모두)
A43: 결함구분 | B43: 신규 | K43: 결함상태 | L43: (다중 항목)
A45: 개수 : 결함ID | B45: 열 레이블 | K45: 개수 : 결함ID | L45: 열 레이블
A46: 행 레이블 | B46: 3자테스트 | C46: 감리테스트 | D46: 공사테스트 | E46: 현업테스트 | F46: 총합계 | K46: 행 레이블 | L46: 3자테스트 | M46: PL테스트 | N46: 감리테스트 | O46: 개발자테스트 | P46: 공사테스트 | Q46: 현업테스트 | R46: 총합계
A47: 1-1차 | C47: 3 | D47: 1 | F47: 4 | K47: A-CDM(CM) | L47: 26 | M47: 11 | N47: 40 | P47: 92 | Q47: 37 | R47: 206
A48: 1-2차 | B48: 1 | C48: 8 | D48: 16 | E48: 5 | F48: 30 | K48: SLOT관리(SLOT) | L48: 78 | M48: 15 | N48: 18 | O48: 1 | P48: 54 | R48: 166
A49: 2-1차 | B49: 1 | D49: 8 | E49: 6 | F49: 15 | K49: 공통관리(AOMS-CA) | L49: 49 | M49: 19 | N49: 16 | P49: 193 | Q49: 42 | R49: 319
A50: 2-2차 | B50: 4 | D50: 9 | E50: 6 | F50: 19 | K50: 공통관리(FIMS-CA) | L50: 56 | M50: 2 | N50: 30 | P50: 185 | Q50: 68 | R50: 341
...

Sheet 테스트 결함목록
A1: 시나리오ID | B1: 테스트차수 | C1: 단계 | D1: 업무모듈명 | E1: 결함ID | F1: 결함내용 | G1: 테스트단계 | H1: PL | I1: 개발자 | J1: 테스터 | K1: 기능유형 | L1: 결함구분 | M1: 결함유형 | N1: 결함상태 | O1: 담당자 | P1: 심각도 | Q1: 조치상태 | R1: 결함등록일 | S1: 결함수정일시
A2: UT-GO12807R | B2: 2-1차 | C2: 6 | D2: 공항운영(GO) | E2: DEF-04688 | F2: [asis값검증] 데이터 순서가 불잍치 | G2: 감리테스트 | H2: 신문호 | I2: 김경준 | J2: 기인보 | K2: Online | L2: 개선/변경 | M2: 데이터 | N2: 결함검토요청 | O2: 신문호 | P2: Major | Q2: 결함검토요청 | R2: 46107.412 | S2: 46107.412
A3: UT-AS32201S | B3: 2-2차 | C3: 6 | D3: 항공통계포털(AS) | E3: DEF-04691 | F3: 열 고정이 안되고 열 고정 해제가 됨 | G3: 감리테스트 | H3: 장은성 | I3: 김경준 | J3: 이동현 | K3: Online | L3: 결함 | M3: 기능 | N3: 결함검토요청 | O3: 장은성 | P3: Major | Q3: 결함검토요청 | R3: 46107.426 | S3: 46107.426
A4: UT-CM30031S | B4: 2-2차 | C4: 6 | D4: A-CDM(CM) | E4: DEF-04692 | F4: 그래프에서 임의의 항목 구분 노출을 OFF로 선택 후 조회 시 이후 그래프에서는 해당 항목 노출을 ON으로 설정할 수 없음(메뉴를 닫았다 다시 열어야 가능함) -> 연료소모 절감량 그래프에서도 동일 현상이 발생하는 것으로 보아 그래프 공통적인 결함일 가능성이 높아보임 -> 항공기 지상이동시간 성과분석(활주로별 유도시간 성과분석) 그래프에서는 조회할 때마다 변수 선택이 초기화(전체 선택)되어 정상 동작하는 것 확인됨 | G4: 감리테스트 | H4: 이지연 | I4: 김단호 | J4: 강진욱 | K4: Online | L4: 결함 | M4: 기능 | N4: 결함검토요청 | O4: 김단호 | P4: Critical | Q4: 결함검토요청 | R4: 46107.426 | S4: 46107.562
A5: UT-CM30031S | B5: 2-2차 | C5: 6 | D5: A-CDM(CM) | E5: DEF-04693 | F5: 정렬 기준이 조회년도/항목구분/출도착은 가운데, 항공기타입별 오염물질 배출절감량은 오른쪽으로 되어있으므로 기준을 통일시킬 것을 권고함 | G5: 감리테스트 | H5: 이지연 | I5: 김단호 | J5: 강진욱 | K5: Online | L5: 개선/변경 | M5: UI | N5: 결함검토요청 | O5: 김단호 | P5: Minor | Q5: 결함검토요청 | R5: 46107.428 | S5: 46107.563
A6: UT-GO-SP126 | B6: 2-2차 | C6: 6 | D6: 공항운영(GO) | E6: DEF-04694 | F6: s-1 에러 | G6: 감리테스트 | H6: 신문호 | I6: 신문호 | J6: 기인보 | K6: 프로시져 | L6: 결함 | M6: 기능 | N6: 결함검토요청 | O6: 신문호 | P6: Major | Q6: 결함검토요청 | R6: 46107.431 | S6: 46107.431
A7: UT-PM10108S | B7: 2-2차 | C7: 6 | D7: 예측관리(PM) | E7: DEF-04695 | F7: -대기인원수 설정 시 시작값이 종료값 보다 크게 입력됨. | G7: 감리테스트 | H7: 염희석 | I7: pmtbd3 | J7: 전태상 | K7: Online | L7: 결함 | M7: 기능 | N7: 결함검토요청 | O7: 염희석 | P7: Minor | Q7: 결함검토요청 | R7: 46107.434 | S7: 46107.434
A8: UT-AS32201S | B8: 2-2차 | C8: 6 | D8: 항공통계포털(AS) | E8: DEF-04703 | F8: X축과 Y축별 최소/최대값 입력하였으나 정상 출력 안됨 | G8: 감리테스트 | H8: 장은성 | I8: 김경준 | J8: 이동현 | K8: Online | L8: 결함 | M8: 기능 | N8: 결함검토요청 | O8: 장은성 | P8: Major | Q8: 결함검토요청 | R8: 46107.45 | S8: 46107.45
A9: UT-CM30033S | B9: 2-2차 | C9: 6 | D9: A-CDM(CM) | E9: DEF-04713 | F9: 그래프에서 변수 노출 OFF 후 재조회 시 변수 노출 ON 불가 | G9: 감리테스트 | H9: 이지연 | I9: 김단호 | J9: 강진욱 | K9: Online | L9: 결함 | M9: 기능 | N9: 결함검토요청 | O9: 김단호 | P9: Critical | Q9: 결함검토요청 | R9: 46107.565 | S9: 46107.631
A10: UT-CM30030S | B10: 2-2차 | C10: 6 | D10: A-CDM(CM) | E10: DEF-04714 | F10: 그래프에서 변수 노출 OFF 후 재조회 시 변수 노출 ON 불가 | G10: 감리테스트 | H10: 이지연 | I10: 김단호 | J10: 강진욱 | K10: Online | L10: 결함 | M10: 기능 | N10: 결함검토요청 | O10: 김단호 | P10: Critical | Q10: 결함검토요청 | R10: 46107.567 | S10: 46107.631
A11: UT-PM10305S | B11: 2-3차 | C11: 3 | D11: 예측관리(PM) | E11: DEF-04723 | F11: 터미널 및 구역을 바꾸고 검색을 해도 차트 모양이 바뀌지 않음 | G11: 3자테스트 | H11: 염희석 | I11: pmtbd2 | J11: 3자테스터공통 | K11: Online | L11: 결함 | M11: 기능 | N11: 결함검토요청 | O11: 염희석 | P11: Major | Q11: 결함검토요청 | R11: 46107.602 | S11: 46107.602
A12: UT-PM10307S | B12: 2-3차 | C12: 3 | D12: 예측관리(PM) | E12: DEF-04739 | F12: 터미널을 바꾸고 검색해도 표 내용이 변하지 않음. | G12: 3자테스트 | H12: 염희석 | I12: pmtbd3 | J12: 3자테스터공통 | K12: Online | L12: 결함 | M12: 기능 | N12: 결함검토요청 | O12: 염희석 | P12: Major | Q12: 결함검토요청 | R12: 46107.658 | S12: 46107.658
A13: UT-SLOTRM007R | B13: 2-2차 | C13: 6 | D13: SLOT관리(SLOT) | E13: DEF-04740 | F13: 조회조건에 맞는 값을 넣고 Arrivals Day Chart 조회시 서버 오류 – 오류 메시지 변경 필요 | G13: 감리테스트 | H13: 김형진 | I13: 서창민 | J13: 신정환 | K13: Online | L13: 결함 | M13: 기능 | N13: 결함검토요청 | O13: 김형진 | P13: Major | Q13: 결함검토요청 | R13: 46107.659 | S13: 46107.659
... A278: UT-PM-SP27 | B278: 1-2차 | C278: 4 | D278: 예측관리(PM) | E278: DEF-01111 | F278: FIMS분리로 시즌배정일을 알 수 없으니 고정값으로 처리 | G278: 공사테스트 | H278: 염희석 | I278: pmtbd3 | J278: 홍석일 | K278: 프로시져 | L278: 개선/변경 | M278: 기능 | N278: 결함검토요청 | O278: 염희석 | P278: Critical | Q278: 결함검토요청 | R278: 45880.605 | S278: 45880.605
A279: UT-CAMN010M | B279: 1-1차 | C279: 4 | D279: 공통관리(FIMS-CA) | E279: DEF-00236 | F279: -결함내용 시스템메시지관리 영역으로 이관 | G279: 공사테스트 | H279: 박영수 | I279: 정연준 | J279: 장수정 | K279: Online | L279: 결함 | M279: 기능 | N279: 결함등록기각 | P279: Major | Q279: 결함등록기각 | R279: 45828.615 | S279: 45841.387
A280: UT-CASY004S | B280: 1-1차 | C280: 4 | D280: 공통관리(FIMS-CA) | E280: DEF-00482 | F280: 오작성 삭제해주세요. | G280: 공사테스트 | H280: 박영수 | I280: 정연준 | J280: 장수정 | K280: Online | L280: 결함 | M280: 기능 | N280: 결함등록기각 | P280: Minor | Q280: 결함등록기각 | R280: 45835.684 | S280: 45838.554
A281: UT-RSPK007S | B281: 1-1차 | C281: 5 | D281: 자원배정(RS) | E281: DEF-00467 | F281: Group에 '전체' 추가 필요 ㅇ전체 추가 불필요하여 제외처리 요청드립니다 | G281: 현업테스트 | H281: 유경섭 | I281: 김훈근 | J281: 권유진 | K281: Online | L281: 개선/변경 | M281: 기능 | N281: 결함등록기각 | P281: Minor | Q281: 결함등록기각 | R281: 45834.654 | S281: 45835.37
A282: UT-MESCM031S | B282: 1-2차 | C282: 3 | D282: 모바일(MES) | E282: DEF-00504 | F282: 시나리오 상에 있는 검색버튼이 없음. 없는 게 맞다면 시나리오 수정 필요함. | G282: 3자테스트 | H282: 임지훈 | I282: 홍성민 | J282: 김단호 | K282: Online | L282: 개선/변경 | M282: UI | N282: 결함등록기각 | P282: Minor | Q282: 결함등록기각 | R282: 45839.555 | S282: 45867.738
A283: UT-AC08009S | B283: 1-2차 | C283: 3 | D283: 항공기관제(AC) | E283: DEF-00522 | F283: 삭제하려는 비고 아이템 코드가 unusing 인 경우에도 사용중인 아이템 코드는 삭제할 수 없습니다 라는 팝업 표출되며 삭제 안됨 | G283: 3자테스트 | H283: 조수일 | I283: 구혜지 | J283: 정수현 | K283: Online | L283: 결함 | M283: 기능 | N283: 결함등록기각 | P283: Major | Q283: 결함등록기각 | R283: 45839.642 | S283: 45839.739
A284: UT-MESCM041S | B284: 1-2차 | C284: 3 | D284: 모바일(MES) | E284: DEF-00527 | F284: TOBT 오름차순 안됨 | G284: 3자테스트 | H284: 임지훈 | I284: 김용진 | J284: 정수현 | K284: Online | L284: 결함 | M284: 데이터 | N284: 결함등록기각 | P284: Minor | Q284: 결함등록기각 | R284: 45839.664 | S284: 45867.737
A285: UT-MESCM041S | B285: 1-2차 | C285: 3 | D285: 모바일(MES) | E285: DEF-00531 | F285: TSAT, TTOT 시간정보 색상이 파란색이 아님 | G285: 3자테스트 | H285: 임지훈 | I285: 김용진 | J285: 정수현 | K285: Online | L285: 결함 | M285: UI | N285: 결함등록기각 | P285: Minor | Q285: 결함등록기각 | R285: 45839.666 | S285: 45866.603
A286: UT-AC01010M | B286: 2-2차 | C286: 3 | D286: 항공기관제(AC) | E286: DEF-00614 | F286: 테스트 결과서 누락 | G286: 3자테스트 | H286: 조수일 | I286: 안소정 | J286: 윤성훈 | K286: Online | L286: 개선/변경 | M286: 문서화 | N286: 결함등록기각 | P286: Minor | Q286: 결함등록기각 | R286: 45841.386 | S286: 45845.379
A287: UT-MESCM043S | B287: 1-2차 | C287: 3 | D287: 모바일(MES) | E287: DEF-00784 | F287: TOBT 3회이상 변경 시 alert이 안나옵니다. | G287: 3자테스트 | H287: 임지훈 | I287: 김용진 | J287: 박상기 | K287: Online | L287: 결함 | M287: UI | N287: 결함등록기각 | P287: Minor | Q287: 결함등록기각 | R287: 45860.42 | S287: 45866.607
A288: UT-MESCM045M | B288: 1-2차 | C288: 3 | D288: 모바일(MES) | E288: DEF-00831 | F288: GATE가 아닌 PAD 항목이 맞는 지 확인이 필요합니다. PAD가 맞으면 결함아닙니다. | G288: 3자테스트 | H288: 임지훈 | I288: 김용진 | J288: 박상기 | K288: Online | L288: 결함 | M288: 기타 | N288: 결함등록기각 | P288: Minor | Q288: 결함등록기각 | R288: 45861.403 | S288: 45866.61
A289: UT-RCCI206M | B289: 1-2차 | C289: 3 | D289: 자원배정차트(RC) | E289: DEF-00797 | F289: ADD Assigment를 하여 3p 를 a07에 배정함 .배정된 바를 변경하려고 하면 변경신청을 누르면 해당값이 사라짐. | G289: 3자테스트 | H289: 이미라 | I289: 문현희 | J289: 김승무 | K289: Online | L289: 결함 | M289: 기능 | N289: 결함등록기각 | P289: Minor | Q289: 결함등록기각 | R289: 45860.591 | S289: 45876.439
A290: UT-MESCM048M | B290: 1-2차 | C290: 3 | D290: 모바일(MES) | E290: DEF-00833 | F290: 제방빙작업 요청 후 -> 출발도착편정보 -> 해당 항공편으로 다시 들어옴 REQ 토글이 비활성화 되어있는 데, 이것이 맞다면 결함이 아닙니다. | G290: 3자테스트 | H290: 임지훈 | I290: 김용진 | J290: 박상기 | K290: Online | L290: 결함 | M290: 프로세스 | N290: 결함등록기각 | P290: Minor | Q290: 결함등록기각 | R290: 45861.425 | S290: 45866.613
... A359: UT-MESCM021S | B359: 1-2차 | C359: 5 | D359: 모바일(MES) | E359: DEF-01793 | F359: 조회된 건은 12건이나 실제 보이는것은 10건임. | G359: 현업테스트 | H359: 임지훈 | I359: 홍성민 | J359: 임유진 | K359: Online | L359: 결함 | M359: 기능 | N359: 결함등록기각 | P359: Critical | Q359: 결함등록기각 | R359: 45898.571 | S359: 45901.446
A360: UT-MESCM021S | B360: 1-2차 | C360: 6 | D360: 모바일(MES) | E360: DEF-01794 | F360: 조회된 건은 12건으로 표기되나 실제 화면에는 10건만 보임 | G360: 감리테스트 | H360: 임지훈 | I360: 홍성민 | J360: 임유진 | K360: Online | L360: 결함 | M360: 기능 | N360: 결함등록기각 | O360: 원유영 | P360: Critical | Q360: 결함등록기각 | R360: 45898.572 | S360: 45901.446
A361: UT-FP-SP23 | B361: 1-2차 | C361: 6 | D361: 운항계획(FP) | E361: DEF-01810 | F361: 'SP_FP_ESB_ALN_CD_CHECK' 식별자가 정의되어야 합니다. 라는 오류 메시지 출력됨 | G361: 감리테스트 | H361: 장경진 | I361: 이인용 | J361: 박광염 | K361: 프로시져 | L361: 신규 | M361: 프로세스 | N361: 결함등록기각 | P361: Minor | Q361: 결함등록기각 | R361: 45902.47 | S361: 45902.59
A362: UT-FP-SP24 | B362: 1-2차 | C362: 6 | D362: 운항계획(FP) | E362: DEF-01811 | F362: "PLS-00201: 'SP_FP_DALY_FLT_NM_CVT' 식별자가 정의되어야 합니다" 라는 오류 메세지 보여짐 | G362: 감리테스트 | H362: 장경진 | I362: 이인용 | J362: 박광염 | K362: 프로시져 | L362: 신규 | M362: 프로세스 | N362: 결함등록기각 | P362: Minor | Q362: 결함등록기각 | R362: 45902.476 | S362: 45902.591
A363: UT-GO-SP44 | B363: 1-2차 | C363: 6 | D363: 공항운영(GO) | E363: DEF-01818 | F363: 1) 실행시 아래와 같은 오류 발생, PARKZONEID 삭제 후 실행 시 실행은 가능하나 데이터는 존재하지 않음 | G363: 감리테스트 | H363: 신문호 | I363: 정병환 | J363: 이장헌 | K363: 프로시져 | L363: 결함 | M363: 프로세스 | N363: 결함등록기각 | O363: 정연욱 | P363: Major | Q363: 결함등록기각 | R363: 45903.656 | S363: 45904.428
A364: UT-GO-SP86 | B364: 1-2차 | C364: 6 | D364: 공항운영(GO) | E364: DEF-01821 | F364: 스크립트 4) 실행 시 데이터 없음 | G364: 감리테스트 | H364: 신문호 | I364: 박정구 | J364: 이장헌 | K364: 프로시져 | L364: 결함 | M364: 기능 | N364: 결함등록기각 | O364: 정연욱 | P364: Major | Q364: 결함등록기각 | R364: 45903.679 | S364: 45904.43
A365: UT-CM20029M | B365: 1-2차 | C365: 4 | D365: A-CDM(CM) | E365: DEF-01785 | F365: ㅇ 기존 입력건 결함이 아닌것으로 확인되어 기각해주세요. ㅇ 현행과 로직을 변경하여 고도화 시스템에 표출할지 현업의견 확인 필요 - (As-Is) EOBT-3 가 들어오지 않았을 때 팝업화면에서 후속 상황 발생시에도 항공기 운항 진행 현황이 AIR에서 멈춰있음. 그림이 더이상 진행되지 않음. - (To-Be) EOBT-3가 들어오지 않은 상황에서도 후속 진행상황 발생 시 그림을 같이 표현해줄지 검토 필요 | G365: 공사테스트 | H365: 이지연 | I365: 김은정 | J365: 장세민 | K365: Online | L365: 개선/변경 | M365: 프로세스 | N365: 결함등록기각 | P365: Major | Q365: 결함등록기각 | R365: 45898.469 | S365: 45918.651
A366: UT-RSPK040M | B366: 1-2차 | C366: 6 | D366: 자원배정(RS) | E366: DEF-01802 | F366: 전체 항공사 조회 총 개수도 하단의 요청 사항 리스트 조회 개수처럼 표기 하도록 개선 요청 | G366: 감리테스트 | H366: 유경섭 | I366: 장동혁 | J366: 박광염 | K366: Online | L366: 개선/변경 | M366: UI | N366: 결함등록기각 | P366: Minor | Q366: 결함등록기각 | R366: 45901.556 | S366: 45919.74
A367: UT-GO12301S | B367: 1-1차 | C367: 5 | D367: 공항운영(GO) | E367: DEF-01954 | F367: 수정/업로드 기능이 없음. 어떻게 입력하는건지? | G367: 현업테스트 | H367: 신문호 | I367: 김경준 | J367: 홍지원 | K367: Online | L367: 개선/변경 | M367: 기능 | N367: 결함등록기각 | P367: Critical | Q367: 결함등록기각 | R367: 45918.629 | S367: 45922.781
A368: UT-GO12301S | B368: 1-1차 | C368: 5 | D368: 공항운영(GO) | E368: DEF-01956 | F368: (공통오류) 기준년월 달력에서 선택시 값이 사라짐 | G368: 현업테스트 | H368: 신문호 | I368: 김경준 | J368: 홍지원 | K368: Online | L368: 개선/변경 | M368: 기능 | N368: 결함등록기각 | P368: Critical | Q368: 결함등록기각 | R368: 45918.63 | S368: 45922.855
A369: UT-MESCM033M | B369: 1-2차 | C369: 4 | D369: 모바일(MES) | E369: DEF-01976 | F369: 도착편 운항정보 [전체] 기능 기능유지 하기로 현업 확인완료 | G369: 공사테스트 | H369: 임지훈 | I369: 홍성민 | J369: 김도연 | K369: Online | L369: 개선/변경 | M369: 기능 | N369: 결함등록기각 | P369: Minor | Q369: 결함등록기각 | R369: 45918.658 | S369: 45919.439
A370: UT-GO11101S | B370: 1-2차 | C370: 5 | D370: 공항운영(GO) | E370: DEF-01854 | F370: GD에러입력 : 에러사유입력시 체크표시 안됨, 입력된 내용 삭제시 저장안됨 | G370: 현업테스트 | H370: 신문호 | I370: 김경준 | J370: 윤지현 | K370: Online | L370: 개선/변경 | M370: 기능 | N370: 결함등록기각 | P370: Major | Q370: 결함등록기각 | R370: 45916.731 | S370: 45922.788
A371: UT-GO11101S | B371: 1-2차 | C371: 5 | D371: 공항운영(GO) | E371: DEF-01856 | F371: 에러편 에러사유입력시 목록에 검정색으로 표시, 재검증시 빨간색으로 표시 | G371: 현업테스트 | H371: 신문호 | I371: 김경준 | J371: 윤지현 | K371: Online | L371: 결함 | M371: 기능 | N371: 결함등록기각 | P371: Major | Q371: 결함등록기각 | R371: 45916.732 | S371: 45922.602
A372: UT-GO11101S | B372: 1-2차 | C372: 5 | D372: 공항운영(GO) | E372: DEF-01857 | F372: 경유지 10번까지 한번에 볼 수 있게 공간 확보 | G372: 현업테스트 | H372: 신문호 | I372: 김경준 | J372: 윤지현 | K372: Online | L372: 개선/변경 | M372: 기능 | N372: 결함등록기각 | P372: Minor | Q372: 결함등록기각 | R372: 45916.733 | S372: 45943.727
...

Sheet Sheet1
U1: 결함ID
U2: DEF-00097 | V2: DEF-00097
A3: 행 레이블 | B3: 개수 : 프로그램ID | U3: DEF-00235 | V3: DEF-00235
A4: 1 | B4: 274 | C4: =COUNTIFS('테스트 결함목록'!$D:$D,Sheet1!A4) -> 0 | D4: =C4/B4 -> 0 | U4: DEF-00236 | V4: DEF-00236
A5: 2 | B5: 507 | C5: =COUNTIFS('테스트 결함목록'!$D:$D,Sheet1!A5) -> 0 | D5: =C5/B5 -> 0 | U5: DEF-00467 | V5: DEF-00467
A6: 4 | B6: 685 | C6: =COUNTIFS('테스트 결함목록'!$D:$D,Sheet1!A6) -> 0 | D6: =C6/B6 -> 0 | U6: DEF-00482 | V6: DEF-00482
A7: 5 | B7: 651 | C7: =COUNTIFS('테스트 결함목록'!$D:$D,Sheet1!A7) -> 0 | D7: =C7/B7 -> 0 | I7: 업무모듈 | J7: 1차 결함 | K7: 1차 개선 | L7: 2차 결함 | M7: 2차 개선 | N7: 총 결함 | U7: DEF-00504 | V7: DEF-00504
A8: 6 | B8: 496 | C8: =COUNTIFS('테스트 결함목록'!$D:$D,Sheet1!A8) -> 0 | D8: =C8/B8 -> 0 | I8: A-CDM(CM) | J8: 13 | K8: 37 | L8: 75 | M8: 82 | N8: 88 | U8: DEF-00522 | V8: DEF-00522
A9: 총합계 | B9: 2613 | C9: =COUNTIFS('테스트 결함목록'!$D:$D,Sheet1!A9) -> 0 | D9: =C9/B9 -> 0 | I9: SLOT관리(SLOT) | J9: 98 | K9: 36 | L9: 21 | M9: 8 | N9: 119 | U9: DEF-00527 | V9: DEF-00527
C10: =COUNTIFS('테스트 결함목록'!$D:$D,Sheet1!A10) -> 0 | D10: =C10/B10 -> #DIV/0! | I10: 공통관리(AOMS-CA) | J10: 121 | K10: 87 | L10: 83 | M10: 27 | N10: 204 | U10: DEF-00531 | V10: DEF-00531
C11: =COUNTIFS('테스트 결함목록'!$D:$D,Sheet1!A11) -> 0 | D11: =C11/B11 -> #DIV/0! | I11: 공통관리(FIMS-CA) | J11: 99 | K11: 76 | L11: 84 | M11: 82 | N11: 183 | U11: DEF-00614 | V11: DEF-00614
C12: =COUNTIFS('테스트 결함목록'!$D:$D,Sheet1!A12) -> 0 | D12: =C12/B12 -> #DIV/0! | I12: 공항운영(GO) | J12: 206 | K12: 133 | L12: 213 | M12: 67 | N12: 419 | U12: DEF-00784 | V12: DEF-00784
C13: =COUNTIFS('테스트 결함목록'!$D:$D,Sheet1!A13) -> 0 | D13: =C13/B13 -> #DIV/0! | I13: 모바일(MES) | J13: 58 | K13: 62 | L13: 52 | M13: 117 | N13: 110 | U13: DEF-00792 | V13: DEF-00792
C14: =COUNTIFS('테스트 결함목록'!$D:$D,Sheet1!A14) -> 0 | D14: =C14/B14 -> #DIV/0! | I14: 모바일(WES) | J14: 20 | K14: 36 | L14: 128 | M14: 124 | N14: 148 | U14: DEF-00797 | V14: DEF-00797
C15: =COUNTIFS('테스트 결함목록'!$D:$D,Sheet1!A15) -> 0 | D15: =C15/B15 -> #DIV/0! | I15: 비상계획(CP) | J15: 0 | K15: 0 | L15: 15 | M15: 29 | N15: 15 | U15: DEF-00831 | V15: DEF-00831
C16: =COUNTIFS('테스트 결함목록'!$D:$D,Sheet1!A16) -> 0 | D16: =C16/B16 -> #DIV/0! | I16: 예측관리(PM) | J16: 46 | K16: 43 | L16: 62 | M16: 57 | N16: 108 | U16: DEF-00833 | V16: DEF-00833
C17: =COUNTIFS('테스트 결함목록'!$D:$D,Sheet1!A17) -> 0 | D17: =C17/B17 -> #DIV/0! | I17: 운항계획(FP) | J17: 72 | K17: 57 | L17: 75 | M17: 113 | N17: 147 | U17: DEF-00839 | V17: DEF-00839
C18: =COUNTIFS('테스트 결함목록'!$D:$D,Sheet1!A18) -> 0 | D18: =C18/B18 -> #DIV/0! | I18: 자원배정(RS) | J18: 95 | K18: 65 | L18: 98 | M18: 66 | N18: 193 | U18: DEF-00840 | V18: DEF-00840
C19: =COUNTIFS('테스트 결함목록'!$D:$D,Sheet1!A19) -> 0 | D19: =C19/B19 -> #DIV/0! | I19: 자원배정엔진(RE) | J19: 3 | K19: 3 | L19: 4 | M19: 7 | N19: 7 | U19: DEF-00850 | V19: DEF-00850
C20: =COUNTIFS('테스트 결함목록'!$D:$D,Sheet1!A20) -> 0 | D20: =C20/B20 -> #DIV/0! | I20: 자원배정차트(RC) | J20: 59 | K20: 30 | L20: 30 | M20: 26 | N20: 89 | U20: DEF-00855 | V20: DEF-00855
C21: =SUM(C4:C20) -> 0 | D21: =C21/B21 -> #DIV/0! | I21: 푸시SW(PUSH) | J21: 4 | K21: 1 | L21: 0 | M21: 0 | N21: 4 | U21: DEF-00888 | V21: DEF-00888
I22: 항공기관제(AC) | J22: 84 | K22: 70 | L22: 116 | M22: 86 | N22: 200 | U22: DEF-00889 | V22: DEF-00889
I23: 항공보안(FS) | J23: 153 | K23: 102 | L23: 40 | M23: 40 | N23: 193 | U23: DEF-00892 | V23: DEF-00892
I24: 항공통계포털(AS) | J24: 0 | K24: 0 | L24: 122 | M24: 79 | N24: 122 | U24: DEF-00893 | V24: DEF-00893
J25: =SUM(J8:J24) -> 1131 | K25: =SUM(K8:K24) -> 838 | L25: =SUM(L8:L24) -> 1218 | M25: =SUM(M8:M24) -> 1010 | N25: =SUM(N8:N24) -> 2349 | U25: DEF-00894 | V25: DEF-00894
U26: DEF-00895 | V26: DEF-00895
U27: DEF-00911 | V27: DEF-00911
U28: DEF-00915 | V28: DEF-00915
U29: DEF-00916 | V29: DEF-00916
U30: DEF-00917 | V30: DEF-00917
U31: DEF-00955 | V31: DEF-00955
U32: DEF-00962 | V32: DEF-00962
U33: DEF-00986 | V33: DEF-00986
U34: DEF-00993 | V34: DEF-00993
U35: DEF-01032 | V35: DEF-01032
U36: DEF-01033 | V36: DEF-01033
U37: DEF-01059 | V37: DEF-01059
... U445: DEF-04708 | V445: DEF-04720
U446: DEF-04720

Sheet 테스트시나리오목록
A1: 업무 | B1: 업무분류1 | C1: 업무분류2 | D1: 기능유형 | E1: 프로그램ID | F1: 프로그램명 | G1: 개발자 | H1: 개발완료계획일 | I1: 개발완료일 | J1: UT_SN_ID | K1: 차수 | L1: 순번 | M1: 3자테스트완료일 | N1: 3자TEST결과 | O1: 순수결함건수 | P1: 3자테스터명 | Q1: 3자최종결과 | R1: 공사테스트완료계획일 | S1: 공사테스트완료일 | T1: 공사테스트결과 | U1: 순수결함건수(공사) | V1: 공사테스터명 | W1: 공사최종결과 | X1: 현업테스트완료계획일 | Y1: 현업테스트완료일 | Z1: 현업테스트결과 | AA1: 순수결함건수(현업) | AB1: 현업테스터명 | AC1: 현업최종결과 | AD1: 감리테스트완료일 | AE1: 감리테스트결과 | AF1: 순수결함건수(감리)
A2: 운항계획(FP) | B2: 기타 | C2: 기타 | D2: 프로시져 | E2: FP-SP23 | F2: SP_FP_ESB_ALN_CD_CHECK,현행운항 항공사코드 등록여부 검사 | G2: 이인용 | H2: 45730 | I2: 45728 | J2: UT-FP-SP23 | K2: 1차 | L2: 2 | M2: 45874 | N2: P | O2: 0 | P2: 이준일 | Q2: P | R2: 45890 | S2: 45891 | T2: P | U2: 0 | V2: 송희영 | W2: P | X2: 45898 | AA2: 0 | AB2: 현업테스터 | AD2: 45952 | AE2: P | AF2: P
A3: 운항계획(FP) | B3: 기타 | C3: 기타 | D3: 프로시져 | E3: FP-SP27 | F3: SP_ESB_BHS_MSA_CSDL,ESB 현행BHS MSA CSDL 메시지수신 | G3: 이인용 | H3: 45737 | I3: 45730 | J3: UT-FP-SP27 | K3: 1차 | L3: 2 | M3: 45874 | N3: P | O3: 0 | P3: 이준일 | Q3: P | R3: 45890 | S3: 45894 | T3: F | U3: 0 | V3: 송희영 | W3: P | X3: 45898 | AA3: 0 | AB3: 현업테스터 | AD3: 45902 | AE3: P | AF3: P
A4: 운항계획(FP) | B4: 기타 | C4: 기타 | D4: 프로시져 | E4: FP-SP34 | F4: SP_FP_ENGINE_COMPLETE,자원배정 완료 후 EAI 메시지처리 | G4: 이인용 | H4: 45751 | I4: 45737.551 | J4: UT-FP-SP34 | K4: 1차 | L4: 2 | M4: 45874 | N4: P | O4: 0 | P4: 이준일 | Q4: P | R4: 45890 | S4: 45891 | T4: F | U4: 0 | V4: 송희영 | W4: P | X4: 45898 | AA4: 0 | AB4: 현업테스터 | AD4: 45902 | AE4: P | AF4: P
A5: 운항계획(FP) | B5: 기타 | C5: 기타 | D5: 프로시져 | E5: FP-SP36 | F5: SP_ESB_AARS_ADM,ESB 현행AARS ADM 메시지수신 | G5: 이인용 | H5: 45758 | I5: 45737 | J5: UT-FP-SP36 | K5: 1차 | L5: 2 | M5: 45874 | N5: P | O5: 0 | P5: 이준일 | Q5: P | R5: 45890 | S5: 45891 | T5: F | U5: 0 | V5: 송희영 | W5: P | X5: 45898 | AA5: 0 | AB5: 현업테스터 | AD5: 45902 | AE5: P | AF5: P
A6: 항공기관제(AC) | B6: 기타 | C6: 기타 | D6: 프로시져 | E6: AC-SP12 | F6: SP_AC_GS_MOVE_DTA_SORT, 항공기 지상이동정보 생성 | G6: 이용혁 | H6: 45758 | I6: 45721.607 | J6: UT-AC-SP12 | K6: 1차 | L6: 1 | M6: 45874 | N6: P | O6: 0 | P6: 윤성훈 | Q6: P | R6: 45890 | S6: 45881 | T6: P | U6: 0 | V6: 정진성 | W6: P | X6: 45898 | AA6: 0 | AB6: 최기현 | AD6: 45903 | AE6: P | AF6: P
A7: 항공기관제(AC) | B7: 기타 | C7: 기타 | D7: 프로시져 | E7: AC-SP13 | F7: SP_AC_PREDACMVT_SND, PAM 메시지 송신 | G7: 이용혁 | H7: 45793 | I7: 45726.592 | J7: UT-AC-SP13 | K7: 1차 | L7: 1 | M7: 45881 | N7: P | O7: 0 | P7: 윤성훈 | Q7: P | R7: 45890 | S7: 45881 | T7: P | U7: 0 | V7: 정진성 | W7: P | X7: 45898 | AA7: 0 | AB7: 최기현 | AD7: 45903 | AE7: P | AF7: P
A8: 항공기관제(AC) | B8: 기타 | C8: 기타 | D8: 프로시져 | E8: AC-SP14 | F8: SP_AC_GRDACMVT_SND, 항공기 지상이동정보 송신 | G8: 이용혁 | H8: 45842 | I8: 45726.592 | J8: UT-AC-SP14 | K8: 1차 | L8: 2 | M8: 45874 | N8: P | O8: 0 | P8: 윤성훈 | Q8: P | R8: 45890 | S8: 45881 | T8: P | U8: 0 | V8: 정진성 | W8: P | X8: 45898 | AA8: 0 | AB8: 최기현 | AD8: 45903 | AE8: P | AF8: P
A9: 항공기관제(AC) | B9: 관제현황관리 | C9: Statistics Data | D9: Online | E9: AC06001S | F9: TOWING | G9: 구혜지 | H9: 46024 | I9: 46029.721 | J9: UT-AC06001S | K9: 2차 | L9: 5 | M9: 46043 | N9: P | O9: 0 | P9: 3자테스터공통 | Q9: P | R9: 46055 | S9: 46064 | T9: P | U9: 0 | V9: 정진성 | W9: P | X9: 46084 | Y9: 46093 | Z9: F | AA9: 0 | AB9: 최기현 | AC9: F
A10: 항공기관제(AC) | B10: 관제현황관리 | C10: Statistics Data | D10: Online | E10: AC06002S | F10: DE-ICING | G10: 구혜지 | H10: 46066 | I10: 45932.445 | J10: UT-AC06002S | K10: 2차 | L10: 6 | O10: 0 | P10: 3자테스터공통 | R10: 46118 | U10: 0 | V10: 정진성 | X10: 46132 | AA10: 0 | AB10: 최기현
A11: 항공기관제(AC) | B11: 관제현황관리 | C11: Statistics Data | D11: Online | E11: AC06007S | F11: TRAFFIC | G11: 구혜지 | H11: 46045 | I11: 45932.446 | J11: UT-AC06007S | K11: 2차 | L11: 5 | M11: 46041 | N11: P | O11: 0 | P11: 3자테스터공통 | Q11: P | R11: 46055 | S11: 46064 | T11: P | U11: 0 | V11: 정진성 | W11: P | X11: 46084 | Y11: 46093 | Z11: F | AA11: 0 | AB11: 최기현 | AC11: P | AD11: 46106 | AE11: P | AF11: P
A12: 항공기관제(AC) | B12: 관제업무설정 | C12: Setting | D12: Online | E12: AC08001S | F12: NOTAM REGISTER | G12: 구혜지 | H12: 46081 | I12: 45827.419 | J12: UT-AC08001S | K12: 2차 | L12: 5 | M12: 46041 | N12: P | O12: 0 | P12: 3자테스터공통 | Q12: P | R12: 46055 | S12: 46063 | T12: P | U12: 0 | V12: 정진성 | W12: P | X12: 46084 | Y12: 46085 | Z12: P | AA12: 0 | AB12: 최기현 | AC12: P | AD12: 46105 | AE12: P | AF12: P
A13: 항공기관제(AC) | B13: 관제업무설정 | C13: Setting | D13: Online | E13: AC08002M | F13: NOTAM 원문 | G13: 구혜지 | H13: 46081 | I13: 45827.419 | J13: UT-AC08002M | K13: 2차 | L13: 5 | M13: 46041 | N13: P | O13: 0 | P13: 3자테스터공통 | Q13: P | R13: 46055 | S13: 46064 | T13: F | U13: 0 | V13: 정진성 | W13: P | X13: 46084 | Y13: 46085 | Z13: F | AA13: 0 | AB13: 최기현 | AC13: P | AD13: 46105 | AE13: P | AF13: P
A14: 항공기관제(AC) | B14: 관제업무설정 | C14: Setting | D14: Online | E14: AC08011S | F14: DE-ICING TIME | G14: 구혜지 | H14: 45770 | I14: 45770.412 | J14: UT-AC08011S | K14: 1차 | L14: 1 | M14: 45821 | N14: P | O14: 0 | P14: 3자테스터공통 | Q14: P | R14: 45890 | S14: 45875 | T14: P | U14: 0 | V14: 정진성 | W14: P | X14: 45898 | Y14: 45924 | Z14: P | AA14: 0 | AB14: 최기현 | AC14: P | AD14: 45901 | AE14: P | AF14: P
A15: 항공기관제(AC) | B15: 관제업무설정 | C15: Setting | D15: Online | E15: AC08018S | F15: DE-ICING PHASE TIME | G15: 안소정 | H15: 46081 | I15: 46048.383 | J15: UT-AC08018S | K15: 2차 | L15: 6 | M15: 46107 | N15: F | O15: 0 | P15: 3자테스터공통 | Q15: P | R15: 46118 | U15: 0 | V15: 정진성 | X15: 46132 | AA15: 0 | AB15: 최기현
A16: 항공기관제(AC) | B16: 관제업무설정 | C16: Setting | D16: Online | E16: AC08012S | F16: MULTIPLE HANDLER | G16: 안소정 | H16: 46080 | I16: 45982.72 | J16: UT-AC08012S | K16: 2차 | L16: 6 | M16: 46107 | N16: F | O16: 0 | P16: 3자테스터공통 | Q16: P | R16: 46118 | U16: 0 | V16: 정진성 | X16: 46132 | AA16: 0 | AB16: 최기현
A17: 공항운영(GO) | B17: 기타 | C17: 기타 | D17: 프로시져 | E17: GO-SP53 | F17: SP_GO_SIGMET_RCV, 악기상 수신메시지 처리 | G17: 정병환 | H17: 45716 | I17: 45720.358 | J17: UT-GO-SP53 | K17: 1차 | L17: 2 | M17: 45877 | N17: P | O17: 0 | P17: 이준일 | Q17: P | R17: 45890 | S17: 45877 | T17: P | U17: 0 | V17: 홍석일 | W17: P | X17: 45898 | AA17: 0 | AB17: 현업테스터 | AD17: 45903 | AE17: P | AF17: P
A18: 공항운영(GO) | B18: 기타 | C18: 기타 | D18: 프로시져 | E18: GO-SP65 | F18: SP_GO_UPDATE_MASTERFILE_RSRV, 승객예약정보 GD 일괄갱신 | G18: 정병환 | H18: 45758 | I18: 45744.638 | J18: UT-GO-SP65 | K18: 1차 | L18: 2 | M18: 45877 | N18: P | O18: 0 | P18: 이준일 | Q18: P | R18: 45890 | S18: 45890 | T18: F | U18: 0 | V18: 홍석일 | W18: P | X18: 45898 | AA18: 0 | AB18: 현업테스터 | AD18: 45903 | AE18: P | AF18: P
A19: 운항계획(FP) | B19: 기타 | C19: 기타 | D19: 프로시져 | E19: FP-SP60 | F19: SP_FP_SSN_ARR_DEP_UPDATE,시즌데이타 변경 | G19: 이인용 | H19: 45835 | I19: 45793.722 | J19: UT-FP-SP60 | K19: 1차 | L19: 2 | M19: 45875 | N19: P | O19: 0 | P19: 이준일 | Q19: P | R19: 45890 | S19: 45894 | T19: P | U19: 0 | V19: 송희영 | W19: P | X19: 45898 | AA19: 0 | AB19: 현업테스터 | AD19: 45902 | AE19: P | AF19: P
A20: 운항계획(FP) | B20: 기타 | C20: 기타 | D20: 프로시져 | E20: FP-SP79 | F20: SP_FP_KALS_ASM_RCV,현행KALS ASM 메시지처리 | G20: 이인용 | H20: 45898 | I20: 45898.413 | J20: UT-FP-SP79 | K20: 2차 | L20: 4 | M20: 45973 | N20: P | O20: 0 | P20: 김진협 | Q20: P | R20: 45996 | S20: 46000 | T20: P | U20: 0 | V20: 송희영 | W20: P | X20: 46017 | AA20: 0 | AB20: 현업테스터 | AD20: 46043 | AE20: P | AF20: P
A21: 운항계획(FP) | B21: 기타 | C21: 기타 | D21: 프로시져 | E21: FP-SP103 | F21: SP_FP_ESTA_AFSCS_RCV,현행ESTA AFSCS 메시지처리 | G21: 이인용 | H21: 45919 | I21: 45898.568 | J21: UT-FP-SP103 | K21: 2차 | L21: 4 | M21: 45973 | N21: P | O21: 0 | P21: 신철진 | Q21: P | R21: 45996 | S21: 45999 | T21: P | U21: 0 | V21: 송희영 | W21: P | X21: 46017 | AA21: 0 | AB21: 현업테스터 | AD21: 46042 | AE21: P | AF21: P
A22: 운항계획(FP) | B22: 기타 | C22: 기타 | D22: 프로시져 | E22: FP-SP109 | F22: SP_FP_DALY_FOIS_AFSARR_PROC_MTY_S,현행FOIS AFSARR 메시지 스케줄처리 | G22: 이인용 | H22: 45954 | I22: 45940.476 | J22: UT-FP-SP109 | K22: 2차 | L22: 5 | M22: 46041 | N22: P | O22: 0 | P22: 신철진 | Q22: P | R22: 46055 | S22: 46062 | T22: F | U22: 0 | V22: 송희영 | W22: P | X22: 46084 | AA22: 0 | AB22: 현업테스터
A23: 운항계획(FP) | B23: 기타 | C23: 기타 | D23: 프로시져 | E23: FP-SP122 | F23: TAIU_TN_FP_DALY_ARR_DEP,현행메인 변경 트리거 | G23: 이인용 | H23: 45982 | I23: 45968.698 | J23: UT-FP-SP122 | K23: 2차 | L23: 5 | M23: 46041 | N23: P | O23: 0 | P23: 3자테스터공통 | Q23: P | R23: 46055 | S23: 46073 | T23: P | U23: 0 | V23: 송희영 | W23: P | X23: 46084 | AA23: 0 | AB23: 현업테스터
A24: 운항계획(FP) | B24: 기타 | C24: 기타 | D24: 프로시져 | E24: FP-SP124 | F24: TAIU_TN_FP_DALY_ARR_DEP_CSHR,현행코드쉐어편 정보변경 트리거 | G24: 이인용 | H24: 45982 | I24: 45982.605 | J24: UT-FP-SP124 | K24: 2차 | L24: 5 | M24: 46041 | N24: P | O24: 0 | P24: 3자테스터공통 | Q24: P | R24: 46055 | S24: 46073 | T24: P | U24: 0 | V24: 송희영 | W24: P | X24: 46084 | AA24: 0 | AB24: 현업테스터
A25: 운항계획(FP) | B25: 기타 | C25: 기타 | D25: 프로시져 | E25: FP-SP139 | F25: SP_FP_FIMSINARR_SND,FIDS 현행운항도착 메시지송신 | G25: 이인용 | H25: 46010 | I25: 46014.408 | J25: UT-FP-SP139 | K25: 2차 | L25: 5 | M25: 46041 | N25: P | O25: 0 | P25: 3자테스터공통 | Q25: P | R25: 46055 | S25: 46064 | T25: P | U25: 0 | V25: 송희영 | W25: P | X25: 46084 | AA25: 0 | AB25: 현업테스터
A26: 운항계획(FP) | B26: 기타 | C26: 기타 | D26: 프로시져 | E26: FP-SP153 | F26: SP_FP_DALY_PUSH_SEND,현행도착출발 푸시메시지 송신 | G26: 이인용 | H26: 46024 | I26: 46022.392 | J26: UT-FP-SP153 | K26: 2차 | L26: 5 | M26: 46041 | N26: P | O26: 0 | P26: 3자테스터공통 | Q26: P | R26: 46055 | S26: 46065 | T26: P | U26: 0 | V26: 송희영 | W26: P | X26: 46084 | AA26: 0 | AB26: 현업테스터
A27: 운항계획(FP) | B27: 기타 | C27: 기타 | D27: 프로시져 | E27: FP-SP159 | F27: SP_FP_RSMAIN_FLD_HST,자원배정 주요필드 변경 이력 생성 | G27: 이인용 | H27: 46052 | I27: 46050.426 | J27: UT-FP-SP159 | K27: 2차 | L27: 6 | M27: 46105 | N27: P | O27: 0 | P27: 3자테스터공통 | Q27: P | R27: 46118 | U27: 0 | V27: 송희영 | X27: 46132 | AA27: 0 | AB27: 현업테스터
A28: 운항계획(FP) | B28: 기타 | C28: 기타 | D28: 프로시져 | E28: FP-SP164 | F28: SP_FP_DLY_RSN_UPDATE,FOIS 지연사유 업데이트 | G28: 이인용 | H28: 46059 | I28: 46051.457 | J28: UT-FP-SP164 | K28: 2차 | L28: 6 | M28: 46105 | N28: P | O28: 0 | P28: 3자테스터공통 | Q28: P | R28: 46118 | U28: 0 | V28: 송희영 | X28: 46132 | AA28: 0 | AB28: 현업테스터
A29: 운항계획(FP) | B29: 기타 | C29: 기타 | D29: 프로시져 | E29: FP-SP168 | F29: SP_FP_PBB_BDGS_RCV,보딩브릿지 상태정보 메시지 업무 반영 | G29: 이인용 | H29: 46059 | I29: 46051.461 | J29: UT-FP-SP168 | K29: 2차 | L29: 6 | M29: 46106 | N29: P | O29: 0 | P29: 3자테스터공통 | Q29: P | R29: 46118 | U29: 0 | V29: 송희영 | X29: 46132 | AA29: 0 | AB29: 현업테스터
A30: 운항계획(FP) | B30: 기타 | C30: 기타 | D30: 프로시져 | E30: FP-SP181 | F30: SP_FP_SSN_CSHR_DELETE_ALN,항공사별 시즌코드쉐어편 삭제 | G30: 이인용 | H30: 46073 | I30: 46059.395 | J30: UT-FP-SP181 | K30: 2차 | L30: 6 | M30: 46106 | N30: P | O30: 0 | P30: 3자테스터공통 | Q30: P | R30: 46118 | U30: 0 | V30: 송희영 | X30: 46132 | AA30: 0 | AB30: 현업테스터
A31: A-CDM(CM) | B31: 마일스톤시간관리 | C31: 마일스톤 시간관리 | D31: Online | E31: CM20028S | F31: 마일스톤변경이력조회 | G31: 김은정 | H31: 45772 | I31: 45737 | J31: UT-CM20028S | K31: 1차 | L31: 1 | M31: 45821 | N31: P | O31: 0 | P31: 3자테스터공통 | Q31: P | R31: 45890 | S31: 45826 | T31: P | U31: 0 | V31: 장세민 | W31: P | X31: 45898 | Y31: 45917 | Z31: F | AA31: 0 | AB31: 김도연 | AC31: P | AD31: 45951 | AE31: P | AF31: P
A32: A-CDM(CM) | B32: 마일스톤시간관리 | C32: 도착편마일스톤관리 | D32: Online | E32: CM20032S | F32: 도착편 운항정보관리(월) | G32: 김은정 | H32: 45898 | I32: 45863.549 | J32: UT-CM20032S | K32: 2차 | L32: 4 | M32: 45971 | N32: P | O32: 0 | P32: 신철진 | Q32: P | R32: 45996 | S32: 45999 | T32: F | U32: 0 | V32: 장세민 | W32: P | X32: 46017 | Y32: 46021 | Z32: P | AA32: 0 | AB32: 현업테스터 | AC32: P | AD32: 46043 | AE32: P | AF32: P
A33: A-CDM(CM) | B33: 마일스톤시간관리 | C33: 출발편마일스톤관리 | D33: Online | E33: CM20030S | F33: 출발편 운항정보관리(월) | G33: 김은정 | H33: 45898 | I33: 45902.611 | J33: UT-CM20030S | K33: 2차 | L33: 5 | M33: 46042 | N33: P | O33: 0 | P33: 3자테스터공통 | Q33: P | R33: 46055 | S33: 46079 | T33: F | U33: 0 | V33: 장세민 | W33: P | X33: 46084 | Y33: 46085 | Z33: F | AA33: 0 | AB33: 현업테스터 | AC33: P | AD33: 46106 | AE33: F | AF33: P
A34: A-CDM(CM) | B34: 마일스톤시간관리 | C34: A-CDM운영현황 | D34: Online | E34: CM10101S | F34: A-CDM 제방빙 기준정보 관리 | G34: 김단호 | H34: 45947 | I34: 45940.435 | J34: UT-CM10101S | K34: 2차 | L34: 4 | M34: 45971 | N34: P | O34: 0 | P34: 신철진 | Q34: P | R34: 45996 | S34: 45996 | T34: F | U34: 0 | V34: 장세민 | W34: P | X34: 46017 | Y34: 46021 | Z34: P | AA34: 0 | AB34: 현업테스터 | AC34: P | AD34: 46048 | AE34: P | AF34: P
A35: 운항계획(FP) | B35: Seasonal schedule | C35: Seasonal Flight List | D35: Online | E35: FPFS022M | F35: SFS Departure Flight Detail | G35: 현영광 | H35: 45772 | I35: 45784.719 | J35: UT-FPFS022M | K35: 1차 | L35: 1 | M35: 45821 | N35: P | O35: 0 | P35: 3자테스터공통 | Q35: P | R35: 45890 | S35: 45827 | T35: F | U35: 0 | V35: 송희영 | W35: P | X35: 45898 | Y35: 45898 | Z35: P | AA35: 0 | AB35: 권유진 | AC35: P | AD35: 45950 | AE35: P | AF35: P
A36: A-CDM(CM) | B36: 기타 | C36: 기타 | D36: 프로시져 | E36: CM-SP8 | F36: FN_CM_GET_EXOT_RAMP,출발편 ESTIMATED TAXING TIME | G36: 이지연 | H36: 45737 | I36: 45709.651 | J36: UT-CM-SP8 | K36: 1차 | L36: 1 | M36: 45874 | N36: P | O36: 0 | P36: 윤성훈 | Q36: P | R36: 45890 | S36: 45828 | T36: P | U36: 0 | V36: 장세민 | W36: P | X36: 45898 | AA36: 0 | AB36: 김도연 | AD36: 45951 | AE36: P | AF36: P
A37: 운항계획(FP) | B37: Daily schedule | C37: Active Flight List | D37: Online | E37: FPFA063M | F37: Link Active Single Flight | G37: 현영광 | H37: 45898 | I37: 45896.755 | J37: UT-FPFA063M | K37: 2차 | L37: 4 | M37: 45972 | N37: P | O37: 0 | P37: 신철진 | Q37: P | R37: 45996 | S37: 45996 | T37: F | U37: 0 | V37: 송희영 | W37: P | X37: 46017 | Y37: 46020 | Z37: P | AA37: 0 | AB37: 현업테스터 | AC37: P | AD37: 46037 | AE37: P | AF37: P
A38: 운항계획(FP) | B38: Daily schedule | C38: ETC | D38: Online | E38: FPFA201S | F38: Active Flight Schedule for others | G38: 현영광 | H38: 46010 | I38: 46003.428 | J38: UT-FPFA201S | K38: 2차 | L38: 5 | M38: 46041 | N38: P | O38: 0 | P38: 3자테스터공통 | Q38: P | R38: 46055 | S38: 46059 | T38: P | U38: 0 | V38: 송희영 | W38: P | X38: 46084 | Y38: 46085 | Z38: F | AA38: 0 | AB38: 현업테스터 | AC38: P | AD38: 46106 | AE38: P | AF38: P
A39: A-CDM(CM) | B39: 기타 | C39: 기타 | D39: 프로시져 | E39: CM-SP34 | F39: SP_CM_OUTBOUND_MLSTN_UPDATE_ADI,출발편 제빙마일스톤 운영-제빙장진입 | G39: 이지연 | H39: 46073 | I39: 46055.746 | J39: UT-CM-SP34 | K39: 2차 | L39: 6 | M39: 46106 | N39: P | O39: 0 | P39: 3자테스터공통 | Q39: P | R39: 46118 | U39: 0 | V39: 장세민 | X39: 46132 | AA39: 0 | AB39: 현업테스터
A40: A-CDM(CM) | B40: 기타 | C40: 기타 | D40: 프로시져 | E40: CM-SP37 | F40: SP_CM_OUTBOUND_MLSTN_UPDATE_ADO,출발편 제빙마일스톤 운영-제빙장진출 | G40: 이지연 | H40: 46073 | I40: 46055.747 | J40: UT-CM-SP37 | K40: 2차 | L40: 6 | M40: 46106 | N40: P | O40: 0 | P40: 3자테스터공통 | Q40: P | R40: 46118 | U40: 0 | V40: 장세민 | X40: 46132 | AA40: 0 | AB40: 현업테스터
...
